Workbook

Sheet PENERIMAAN OBAT PKD
A1: DAFTAR PENERIMAAN OBAT PKD
A2: UPT PUSKESMAS SUKAMAJU
A3: TAHUN 2026
A5: Bulan Januari | N5: 12
A6: NO | B6: Nama Obat | C6: SATUAN | D6: PENERIMAAN OBAT | H6: TOTAL
D7: 46114 | E7: 46267
A8: 1 | B8: 2 | C8: 3 | D8: 4 | E8: 5 | F8: 6 | G8: 7 | H8: 8
A9: 1 | B9: Air untuk injeksi amp 25 ml | C9: Ampul | D9: 30 | H9: =SUM(D9:G9) -> 30
A10: =A9+1 -> 2 | B10: Alopurinol tab 300 mg | C10: Ktk @ 100 tablet | D10: 500 | H10: =SUM(D10:G10) -> 500
A11: =A10+1 -> 3 | B11: Ambroxol Sirup | C11: Botol | H11: =SUM(D11:G11) -> 0
A12: =A11+1 -> 4 | B12: Amlodipin tab 5 mg | C12: Ktk 50 Tablet | D12: 2000 | H12: =SUM(D12:G12) -> 2000
A13: =A12+1 -> 5 | B13: Amlodipin Tablet 10 mg | C13: Tablet | D13: 3000 | H13: =SUM(D13:G13) -> 3000
A14: =A13+1 -> 6 | B14: Amoksisilin sirup kering 125 mg/5 ml | C14: Botol | H14: =SUM(D14:G14) -> 0
A15: =A14+1 -> 7 | B15: Amoksisilin tab 500 mg | C15: Ktk @100 kaplet | D15: 1500 | H15: =SUM(D15:G15) -> 1500
A16: =A15+1 -> 8 | B16: Anestetik lokal gigi kombinasi : lidokain hcl 2% + epinefrin 1 : 80.000 inj 2 ml | C16: Ampul | D16: 100 | H16: =SUM(D16:G16) -> 100
A17: =A16+1 -> 9 | B17: Antasida, kombinasi : aluminium hidroksida 200 mg + magnesium hidroksida 200 mg | C17: Btl 60 ml | D17: 50 | H17: =SUM(D17:G17) -> 50
A18: =A17+1 -> 10 | B18: Antasida, kombinasi : aluminium hidroksida 200 mg + magnesium hidroksida 200 mg | C18: Ktk @ 100 tablet | D18: 1000 | H18: =SUM(D18:G18) -> 1000
A19: =A18+1 -> 11 | B19: Anti Tetanus Serum ( ATS ) 1500 IU | C19: Ampul | H19: =SUM(D19:G19) -> 0
A20: =A19+1 -> 12 | B20: Antihemoroid, kombinasi: bismut subgalat 150 mg + heksaklorofen 2,5 mg + lidokain lidokain 10 mg+ seng oksida 120 mg + sup ad 2 g | C20: Suppositoria | H20: =SUM(D20:G20) -> 0
A21: =A20+1 -> 13 | B21: Asam asetilsalisilat tab 80 mg (Miniaspi) | C21: Ktk @ 100 tablet | H21: =SUM(D21:G21) -> 0
A22: =A21+1 -> 14 | B22: Asam askorbat (vitamin C) tab 250 mg | C22: Ktk @ 100 tablet | H22: =SUM(D22:G22) -> 0
A23: =A22+1 -> 15 | B23: Asam askorbat (vitamin C) tab 50 mg | C23: Ktk @ 100 tablet | H23: =SUM(D23:G23) -> 0
A24: =A23+1 -> 16 | B24: Asam mefenamat kaps 500 mg | C24: Ktk @ 100 tablet | D24: 1500 | H24: =SUM(D24:G24) -> 1500
A25: =A24+1 -> 17 | B25: Asam traneksamat inj 50 mg/ml | C25: Ampul | H25: =SUM(D25:G25) -> 0
A26: =A25+1 -> 18 | B26: Asiklovir Krim | C26: tube | D26: 25 | H26: =SUM(D26:G26) -> 25
A27: =A26+1 -> 19 | B27: Asiklovir tab 400 mg | C27: Ktk 5 x 10 Tablet | H27: =SUM(D27:G27) -> 0
A28: =A27+1 -> 20 | B28: Atapulgit ( New Antides ) tab 600 mg | C28: Ktk 150 Tablet | H28: =SUM(D28:G28) -> 0
A29: =A28+1 -> 21 | B29: Atorvastatin 20 mg | C29: Tablet | D29: 2000 | H29: =SUM(D29:G29) -> 2000
A30: =A29+1 -> 22 | B30: Atropin inj 0,25 mg/ml (i.m./i.v./s.k) | C30: Ampul | H30: =SUM(D30:G30) -> 0
A31: =A30+1 -> 23 | B31: Bedak Salicyl 2 % 60 gr | C31: Pot | H31: =SUM(D31:G31) -> 0
A32: =A31+1 -> 24 | B32: Betahistin Mesilat tab 6 mg | C32: Ktk 10 x 10 tablet | H32: =SUM(D32:G32) -> 0
A33: =A32+1 -> 25 | B33: Betametason krim 0,1% | C33: tube @ 5 gram | H33: =SUM(D33:G33) -> 0
A34: =A33+1 -> 26 | B34: Bisakodil sup 10 mg ( Dulcolax ) | C34: Suppositoria | H34: =SUM(D34:G34) -> 0
A35: =A34+1 -> 27 | B35: Bisakodil sup 5 mg ( Dulcolax ) | C35: Suppositoria | H35: =SUM(D35:G35) -> 0
A36: =A35+1 -> 28 | B36: Colcitin 0.5 gr | C36: Ktk 30 tab | H36: =SUM(D36:G36) -> 0
A37: =A36+1 -> 29 | B37: Deksametason tab 0,5 mg | C37: Ktk @ 100 tablet | E37: 1500 | H37: =SUM(D37:G37) -> 1500
A38: =A37+1 -> 30 | B38: Deksametason inj 5 mg/ml (i.v./i.m.) | C38: Ampul | H38: =SUM(D38:G38) -> 0
A39: =A38+1 -> 31 | B39: Dextrose 40% | C39: Botol | H39: =SUM(D39:G39) -> 0
A40: =A39+1 -> 32 | B40: Diazepam inj 10 mg/ 2 ml ( i v./i.m .) stesolid | C40: Ampul @ 2 ml | H40: =SUM(D40:G40) -> 0
A41: =A40+1 -> 33 | B41: Diazepam lar rektal 5 mg/2,5 ml ( Stesolid ) | C41: Tube 5 mg/2,5 ml | H41: =SUM(D41:G41) -> 0
...

Sheet PENERIMAAN OBAT PROGRAM
A1: DAFTAR PENERIMAAN OBAT PROGRAM
A2: UPT PUSKESMAS SUKAMAJU
A3: TAHUN 2026
A5: ='PENERIMAAN OBAT PKD'!A5:B5 -> Bulan Januari | M5: 12
A6: NO | B6: Nama Obat | C6: SATUAN | D6: PENERIMAAN OBAT | G6: TOTAL
D7: 46267
A8: 1 | B8: 2 | C8: 3 | D8: 4 | G8: 5
A9: 1 | B9: GIZI
A10: 2 | B10: Mineral Mix | C10: Sacshet | G10: =SUM(D10:D10) -> 0
A11: 3 | B11: Supralysin | C11: Botol | G11: =SUM(D11:D11) -> 0
A12: 4 | B12: Tabelt Tambah Darah | C12: Tablet | D12: 20000 | G12: =SUM(D12:D12) -> 20000
A13: 5 | B13: Taburia | C13: Sacshet | G13: =SUM(D13:D13) -> 0
A14: 6 | B14: Vitamin A Biru 10000 iu | C14: Kapsul | G14: =SUM(D14:D14) -> 0
A15: 7 | B15: Vitamin A Merah 20000 iu | C15: Kapsul | G15: =SUM(D15:D15) -> 0
A16: 8 | G16: =SUM(D16:D16) -> 0
A17: 9 | G17: =SUM(D17:D17) -> 0
A18: 10 | G18: =SUM(D18:D18) -> 0
A19: 11 | B19: OBAT KESEHATAN IBU ANAK
A20: 12 | B20: Phenobarbital Injeksi | C20: Ampul | G20: =SUM(D20:F20) -> 0
A21: 13 | B21: Ampicilin injeksi | C21: vial | G21: =SUM(D21:F21) -> 0
A22: 14 | B22: Calsii Gluconas | C22: Ampul | G22: =SUM(D22:F22) -> 0
A23: 15 | B23: Dextrosa 5% | C23: Botol | G23: =SUM(D23:F23) -> 0
A24: 16 | B24: Diazepam Injeksi | C24: Ampul | G24: =SUM(D24:F24) -> 0
A25: 17 | B25: Fitomenadion injeksi 2 mg/ ml | C25: Ampul | G25: =SUM(D25:F25) -> 0
A26: 18 | B26: Methyl Ergometrine inje 2 mg | C26: Ampul | G26: =SUM(D26:F26) -> 0
A27: 19 | B27: Mgso4 20 % | C27: Ampul | G27: =SUM(D27:F27) -> 0
A28: 20 | B28: Mgso4 40 % | C28: Ampul | G28: =SUM(D28:F28) -> 0
A29: 21 | B29: Oksitosin Injeksi | C29: Ampul | F29: 50 | G29: =SUM(D29:F29) -> 50
A30: 22 | B30: Oxytetra Salep mata 1 % | C30: Tube | G30: =SUM(D30:F30) -> 0
A31: 23 | B31: Proten Gold Vanila | G31: =SUM(D31:F31) -> 0
A32: 24 | B32: Levothyrokxine | C32: Tablet | G32: =SUM(D32:F32) -> 0
A33: 25 | B33: Multivitamin MMS | C33: Botol | D33: 409 | G33: =SUM(D33:F33) -> 409
A34: 26 | B34: Kloramfenikol Salep Mata | C34: Tube | G34: =SUM(D34:F34) -> 0
A35: 27 | G35: =SUM(D35:F35) -> 0
A36: 28 | B36: OBAT PROGRAM MALARIA
A37: 29 | B37: ACT ( Obat Antimalaria )/DHP | C37: Tablet | G37: =SUM(D37:F37) -> 0
A38: 30 | B38: Artesunat Injeksi 60mg/ml | C38: vial | G38: =SUM(D38:F38) -> 0
A39: 31 | B39: Giemsa | C39: Botol | G39: =SUM(D39:F39) -> 0
A40: 32 | B40: Primaquin | C40: Tablet | G40: =SUM(D40:F40) -> 0
A41: 33 | B41: RDT Chikungunya | C41: Pcs | G41: =SUM(D41:F41) -> 0
...

Sheet DISTRIBUSI
A1: LAPORAN DISTRIBUSI OBAT UNIT PELAYANAN
A2: UPT PUSKESMAS SUKAMAJU
A3: TAHUN 2025
R5: BULAN | S5: : Januari | AT5: 12
D6: 17 dn 25 | E6: 12 a | F6: 12 b | G6: 17 b | I6: 12 c | J6: 21 | K6: 13 | L6: 13 b | M6: 10 | R6: TAHUN | S6: : 2026
A7: NO | B7: Nama Obat | C7: SATUAN | D7: SAPTA MARGA | E7: SALULEMO | F7: KALUKU | G7: TAMBOKE | H7: MINANGA TALLU | I7: LAMPUAWA | J7: T. INDAH | K7: T.SARI | L7: MULYASARI | M7: KETULUNGAN | N7: WONOSARI | O7: TOLANGI | P7: SUKADAMAI | Q7: PONGKASE | R7: APOTIK | S7: UGD | T7: APOTIK 2 | U7: RI | V7: RB | W7: POLI | X7: LAB | Y7: LAIN-LAIN | Z7: JUMLAH | AB7: sisa stok | AH7: APOTIK | BM7: JUMLAH | BO7: UGD | CT7: JUMLAH | CU7: APOTIK2 | CV7: APOTEK 2 | EA7: JUMLAH | EB7: RI | EC7: RAWAT INAP | FH7: JUMLAH | FJ7: RUANG BERSALIN | GO7: JUMLAH | GQ7: POLI (KIA, POLI UMUM, POLI GIGI) | HV7: JUMLAH | HX7: LABORATORIUM | JC7: JUMLAH | JE7: DLL | KJ7: JUMLAH
BN8: UGD | FI8: RB | GP8: POLI | HW8: LAB | JD8: DLL
A9: 1 | B9: 2 | C9: 3 | D9: 4 | E9: 5 | F9: 6 | G9: 7 | H9: 8 | I9: 9 | J9: 10 | K9: 11 | L9: 12 | M9: 13 | N9: 14 | O9: 15 | P9: 16 | Q9: 17 | R9: 18 | S9: 19 | T9: 20 | U9: 21 | V9: 22 | W9: 23 | X9: 24 | Y9: 25 | Z9: 26 | AH9: 1 | AI9: 2 | AJ9: 3 | AK9: 4 | AL9: 5 | AM9: 6 | AN9: 7 | AO9: 8 | AP9: 9 | AQ9: 10 | AR9: 11 | AS9: 12 | AT9: 13 | AU9: 14 | AV9: 15 | AW9: 16 | AX9: 17 | AY9: 18 | AZ9: 19 | BA9: 20 | BB9: 21 | BC9: 22 | BD9: 23 | BE9: 24 | BF9: 25 | BG9: 26 | BH9: 27 | BI9: 28 | BJ9: 29 | BK9: 30 | BL9: 31 | BO9: 1 | BP9: 2 | BQ9: 3 | BR9: 4 | BS9: 5 | BT9: 6 | BU9: 7 | BV9: 8 | BW9: 9 | BX9: 10 | BY9: 11 | BZ9: 12 | CA9: 13 | CB9: 14 | CC9: 15 | CD9: 16 | CE9: 17 | CF9: 18 | CG9: 19 | CH9: 20 | CI9: 21 | CJ9: 22 | CK9: 23 | CL9: 24 | CM9: 25 | CN9: 26 | CO9: 27 | CP9: 28 | CQ9: 29 | CR9: 30 | CS9: 31 | CV9: 1 | CW9: 2 | CX9: 3 | CY9: 4 | CZ9: 5 | DA9: 6 | DB9: 7 | DC9: 8 | DD9: 9 | DE9: 10 | DF9: 11 | DG9: 12 | DH9: 13 | DI9: 14 | DJ9: 15 | DK9: 16 | DL9: 17 | DM9: 18 | DN9: 19 | DO9: 20 | DP9: 21 | DQ9: 22 | DR9: 23 | DS9: 24 | DT9: 25 | DU9: 26 | DV9: 27 | DW9: 28 | DX9: 29 | DY9: 30 | DZ9: 31 | EC9: 1 | ED9: 2 | EE9: 3 | EF9: 4 | EG9: 5 | EH9: 6 | EI9: 7 | EJ9: 8 | EK9: 9 | EL9: 10 | EM9: 11 | EN9: 12 | EO9: 13 | EP9: 14 | EQ9: 15 | ER9: 16 | ES9: 17 | ET9: 18 | EU9: 19 | EV9: 20 | EW9: 21 | EX9: 22 | EY9: 23 | EZ9: 24 | FA9: 25 | FB9: 26 | FC9: 27 | FD9: 28 | FE9: 29 | FF9: 30 | FG9: 31 | FJ9: 1 | FK9: 2 | FL9: 3 | FM9: 4 | FN9: 5 | FO9: 6 | FP9: 7 | FQ9: 8 | FR9: 9 | FS9: 10 | FT9: 11 | FU9: 12 | FV9: 13 | FW9: 14 | FX9: 15 | FY9: 16 | FZ9: 17 | GA9: 18 | GB9: 19 | GC9: 20 | GD9: 21 | GE9: 22 | GF9: 23 | GG9: 24 | GH9: 25 | GI9: 26 | GJ9: 27 | GK9: 28 | GL9: 29 | GM9: 30 | GN9: 31 | GQ9: 1 | GR9: 2 | GS9: 3 | GT9: 4 | GU9: 5 | GV9: 6 | GW9: 7 | GX9: 8 | GY9: 9 | GZ9: 10 | HA9: 11 | HB9: 12 | HC9: 13 | HD9: 14 | HE9: 15 | HF9: 16 | HG9: 17 | HH9: 18 | HI9: 19 | HJ9: 20 | HK9: 21 | HL9: 22 | HM9: 23 | HN9: 24 | HO9: 25 | HP9: 26 | HQ9: 27 | HR9: 28 | HS9: 29 | HT9: 30 | HU9: 31 | HX9: 1 | HY9: 2 | HZ9: 3 | IA9: 4 | IB9: 5 | IC9: 6 | ID9: 7 | IE9: 8 | IF9: 9 | IG9: 10 | IH9: 11 | II9: 12 | IJ9: 13 | IK9: 14 | IL9: 15 | IM9: 16 | IN9: 17 | IO9: 18 | IP9: 19 | IQ9: 20 | IR9: 21 | IS9: 22 | IT9: 23 | IU9: 24 | IV9: 25 | IW9: 26 | IX9: 27 | IY9: 28 | IZ9: 29 | JA9: 30 | JB9: 31 | JE9: 1 | JF9: 2 | JG9: 3 | JH9: 4 | JI9: 5 | JJ9: 6 | JK9: 7 | JL9: 8 | JM9: 9 | JN9: 10 | JO9: 11 | JP9: 12 | JQ9: 13 | JR9: 14 | JS9: 15 | JT9: 16 | JU9: 17 | JV9: 18 | JW9: 19 | JX9: 20 | JY9: 21 | JZ9: 22 | KA9: 23 | KB9: 24 | KC9: 25 | KD9: 26 | KE9: 27 | KF9: 28 | KG9: 29 | KH9: 30 | KI9: 31
A10: 1 | B10: Air untuk injeksi amp 25 ml | C10: Ampul | R10: =BM10 -> 60 | S10: =CT10 -> 0 | T10: =EA10 -> 0 | U10: =FH10 -> 0 | V10: =GO10 -> 0 | W10: =HV10 -> 0 | X10: =JC10 -> 0 | Y10: =KJ10 -> 0 | Z10: =SUM(D10:Y10) -> 60 | AB10: ='LPLPO GUDANG'!H15 -> 0 | AP10: 60 | BM10: =SUM(AH10:BL10) -> 60 | CT10: =SUM(BO10:CS10) -> 0 | EA10: =SUM(CV10:DZ10) -> 0 | FH10: =SUM(EC10:FG10) -> 0 | GO10: =SUM(FJ10:GN10) -> 0 | HV10: =SUM(GQ10:HU10) -> 0 | JC10: =SUM(HX10:JB10) -> 0 | KJ10: =SUM(JE10:KI10) -> 0
A11: =A10+1 -> 2 | B11: Alopurinol tab 300 mg | C11: Ktk @ 100 tablet | R11: =BM11 -> 500 | S11: =CT11 -> 0 | T11: =EA11 -> 0 | U11: =FH11 -> 0 | V11: =GO11 -> 0 | W11: =HV11 -> 0 | X11: =JC11 -> 0 | Y11: =KJ11 -> 0 | Z11: =SUM(D11:Y11) -> 500 | AB11: ='LPLPO GUDANG'!H16 -> 500 | BF11: 500 | BM11: =SUM(AH11:BL11) -> 500 | CT11: =SUM(BO11:CS11) -> 0 | EA11: =SUM(CV11:DZ11) -> 0 | FH11: =SUM(EC11:FG11) -> 0 | GO11: =SUM(FJ11:GN11) -> 0 | HV11: =SUM(GQ11:HU11) -> 0 | JC11: =SUM(HX11:JB11) -> 0 | KJ11: =SUM(JE11:KI11) -> 0
A12: =A11+1 -> 3 | B12: Ambroxol Sirup | C12: Botol | R12: =BM12 -> 30 | S12: =CT12 -> 0 | T12: =EA12 -> 0 | U12: =FH12 -> 0 | V12: =GO12 -> 0 | W12: =HV12 -> 0 | X12: =JC12 -> 0 | Y12: =KJ12 -> 0 | Z12: =SUM(D12:Y12) -> 30 | AB12: ='LPLPO GUDANG'!H17 -> 15 | BE12: 30 | BM12: =SUM(AH12:BL12) -> 30 | CT12: =SUM(BO12:CS12) -> 0 | EA12: =SUM(CV12:DZ12) -> 0 | FH12: =SUM(EC12:FG12) -> 0 | GO12: =SUM(FJ12:GN12) -> 0 | HV12: =SUM(GQ12:HU12) -> 0 | JC12: =SUM(HX12:JB12) -> 0 | KJ12: =SUM(JE12:KI12) -> 0
A13: =A12+1 -> 4 | B13: Amlodipin tab 5 mg | C13: Ktk 50 Tablet | I13: 100 | R13: =BM13 -> 2000 | S13: =CT13 -> 0 | T13: =EA13 -> 100 | U13: =FH13 -> 0 | V13: =GO13 -> 0 | W13: =HV13 -> 0 | X13: =JC13 -> 0 | Y13: =KJ13 -> 0 | Z13: =SUM(D13:Y13) -> 2200 | AB13: ='LPLPO GUDANG'!H18 -> 1800 | BF13: 2000 | BM13: =SUM(AH13:BL13) -> 2000 | CT13: =SUM(BO13:CS13) -> 0 | DL13: 100 | EA13: =SUM(CV13:DZ13) -> 100 | FH13: =SUM(EC13:FG13) -> 0 | GO13: =SUM(FJ13:GN13) -> 0 | HV13: =SUM(GQ13:HU13) -> 0 | JC13: =SUM(HX13:JB13) -> 0 | KJ13: =SUM(JE13:KI13) -> 0
A14: =A13+1 -> 5 | B14: Amlodipin Tablet 10 mg | C14: Tablet | R14: =BM14 -> 3000 | S14: =CT14 -> 0 | T14: =EA14 -> 200 | U14: =FH14 -> 0 | V14: =GO14 -> 0 | W14: =HV14 -> 0 | X14: =JC14 -> 0 | Y14: =KJ14 -> 0 | Z14: =SUM(D14:Y14) -> 3200 | AB14: ='LPLPO GUDANG'!H19 -> 1800 | BF14: 3000 | BM14: =SUM(AH14:BL14) -> 3000 | CT14: =SUM(BO14:CS14) -> 0 | CX14: 200 | EA14: =SUM(CV14:DZ14) -> 200 | FH14: =SUM(EC14:FG14) -> 0 | GO14: =SUM(FJ14:GN14) -> 0 | HV14: =SUM(GQ14:HU14) -> 0 | JC14: =SUM(HX14:JB14) -> 0 | KJ14: =SUM(JE14:KI14) -> 0
A15: =A14+1 -> 6 | B15: Amoksisilin sirup kering 125 mg/5 ml | C15: Botol | R15: =BM15 -> 0 | S15: =CT15 -> 0 | T15: =EA15 -> 0 | U15: =FH15 -> 0 | V15: =GO15 -> 0 | W15: =HV15 -> 0 | X15: =JC15 -> 0 | Y15: =KJ15 -> 0 | Z15: =SUM(D15:Y15) -> 0 | AB15: ='LPLPO GUDANG'!H20 -> 135 | AC15: -1 | BM15: =SUM(AH15:BL15) -> 0 | CT15: =SUM(BO15:CS15) -> 0 | EA15: =SUM(CV15:DZ15) -> 0 | FH15: =SUM(EC15:FG15) -> 0 | GO15: =SUM(FJ15:GN15) -> 0 | HV15: =SUM(GQ15:HU15) -> 0 | JC15: =SUM(HX15:JB15) -> 0 | KJ15: =SUM(JE15:KI15) -> 0
A16: =A15+1 -> 7 | B16: Amoksisilin tab 500 mg | C16: Ktk @100 kaplet | J16: 100 | K16: 100 | R16: =BM16 -> 0 | S16: =CT16 -> 0 | T16: =EA16 -> 200 | U16: =FH16 -> 0 | V16: =GO16 -> 0 | W16: =HV16 -> 0 | X16: =JC16 -> 0 | Y16: =KJ16 -> 0 | Z16: =SUM(D16:Y16) -> 400 | AB16: ='LPLPO GUDANG'!H21 -> 3100 | AC16: -100 | BM16: =SUM(AH16:BL16) -> 0 | CT16: =SUM(BO16:CS16) -> 0 | CX16: 200 | EA16: =SUM(CV16:DZ16) -> 200 | FH16: =SUM(EC16:FG16) -> 0 | GO16: =SUM(FJ16:GN16) -> 0 | HV16: =SUM(GQ16:HU16) -> 0 | JC16: =SUM(HX16:JB16) -> 0 | KJ16: =SUM(JE16:KI16) -> 0
A17: =A16+1 -> 8 | B17: Anestetik lokal gigi kombinasi : lidokain hcl 2% + epinefrin 1 : 80.000 inj 2 ml | C17: Ampul | R17: =BM17 -> 35 | S17: =CT17 -> 0 | T17: =EA17 -> 0 | U17: =FH17 -> 0 | V17: =GO17 -> 15 | W17: =HV17 -> 50 | X17: =JC17 -> 0 | Y17: =KJ17 -> 0 | Z17: =SUM(D17:Y17) -> 100 | AB17: ='LPLPO GUDANG'!H22 -> 0 | BE17: 35 | BM17: =SUM(AH17:BL17) -> 35 | CT17: =SUM(BO17:CS17) -> 0 | EA17: =SUM(CV17:DZ17) -> 0 | FH17: =SUM(EC17:FG17) -> 0 | GG17: 15 | GO17: =SUM(FJ17:GN17) -> 15 | HJ17: 50 | HV17: =SUM(GQ17:HU17) -> 50 | JC17: =SUM(HX17:JB17) -> 0 | KJ17: =SUM(JE17:KI17) -> 0
A18: =A17+1 -> 9 | B18: Antasida, kombinasi : aluminium hidroksida 200 mg + magnesium hidroksida 200 mg | C18: Btl 60 ml | R18: =BM18 -> 50 | S18: =CT18 -> 0 | T18: =EA18 -> 10 | U18: =FH18 -> 0 | V18: =GO18 -> 0 | W18: =HV18 -> 0 | X18: =JC18 -> 0 | Y18: =KJ18 -> 0 | Z18: =SUM(D18:Y18) -> 60 | AB18: ='LPLPO GUDANG'!H23 -> 80 | AX18: 50 | BM18: =SUM(AH18:BL18) -> 50 | CT18: =SUM(BO18:CS18) -> 0 | DL18: 10 | EA18: =SUM(CV18:DZ18) -> 10 | FH18: =SUM(EC18:FG18) -> 0 | GO18: =SUM(FJ18:GN18) -> 0 | HV18: =SUM(GQ18:HU18) -> 0 | JC18: =SUM(HX18:JB18) -> 0 | KJ18: =SUM(JE18:KI18) -> 0
A19: =A18+1 -> 10 | B19: Antasida, kombinasi : aluminium hidroksida 200 mg + magnesium hidroksida 200 mg | C19: Ktk @ 100 tablet | F19: 100 | J19: 100 | K19: 100 | R19: =BM19 -> 0 | S19: =CT19 -> 0 | T19: =EA19 -> 200 | U19: =FH19 -> 0 | V19: =GO19 -> 0 | W19: =HV19 -> 0 | X19: =JC19 -> 0 | Y19: =KJ19 -> 0 | Z19: =SUM(D19:Y19) -> 500 | AB19: ='LPLPO GUDANG'!H24 -> 1900 | BM19: =SUM(AH19:BL19) -> 0 | CT19: =SUM(BO19:CS19) -> 0 | DL19: 200 | EA19: =SUM(CV19:DZ19) -> 200 | FH19: =SUM(EC19:FG19) -> 0 | GO19: =SUM(FJ19:GN19) -> 0 | HV19: =SUM(GQ19:HU19) -> 0 | JC19: =SUM(HX19:JB19) -> 0 | KJ19: =SUM(JE19:KI19) -> 0
A20: =A19+1 -> 11 | B20: Anti Tetanus Serum ( ATS ) 1500 IU | C20: Ampul | R20: =BM20 -> 0 | S20: =CT20 -> 0 | T20: =EA20 -> 0 | U20: =FH20 -> 0 | V20: =GO20 -> 0 | W20: =HV20 -> 0 | X20: =JC20 -> 0 | Y20: =KJ20 -> 0 | Z20: =SUM(D20:Y20) -> 0 | AB20: ='LPLPO GUDANG'!H25 -> 0 | BM20: =SUM(AH20:BL20) -> 0 | CT20: =SUM(BO20:CS20) -> 0 | EA20: =SUM(CV20:DZ20) -> 0 | FH20: =SUM(EC20:FG20) -> 0 | GO20: =SUM(FJ20:GN20) -> 0 | HV20: =SUM(GQ20:HU20) -> 0 | JC20: =SUM(HX20:JB20) -> 0 | KJ20: =SUM(JE20:KI20) -> 0
A21: =A20+1 -> 12 | B21: Antihemoroid, kombinasi: bismut subgalat 150 mg + heksaklorofen 2,5 mg + lidokain lidokain 10 mg+ seng oksida 120 mg + sup ad 2 g | C21: Suppositoria | R21: =BM21 -> 0 | S21: =CT21 -> 0 | T21: =EA21 -> 0 | U21: =FH21 -> 0 | V21: =GO21 -> 0 | W21: =HV21 -> 0 | X21: =JC21 -> 0 | Y21: =KJ21 -> 0 | Z21: =SUM(D21:Y21) -> 0 | AB21: ='LPLPO GUDANG'!H26 -> 20 | BM21: =SUM(AH21:BL21) -> 0 | CT21: =SUM(BO21:CS21) -> 0 | EA21: =SUM(CV21:DZ21) -> 0 | FH21: =SUM(EC21:FG21) -> 0 | GO21: =SUM(FJ21:GN21) -> 0 | HV21: =SUM(GQ21:HU21) -> 0 | JC21: =SUM(HX21:JB21) -> 0 | KJ21: =SUM(JE21:KI21) -> 0
A22: =A21+1 -> 13 | B22: Asam asetilsalisilat tab 80 mg (Miniaspi) | C22: Ktk @ 100 tablet | R22: =BM22 -> 0 | S22: =CT22 -> 0 | T22: =EA22 -> 0 | U22: =FH22 -> 0 | V22: =GO22 -> 0 | W22: =HV22 -> 0 | X22: =JC22 -> 0 | Y22: =KJ22 -> 0 | Z22: =SUM(D22:Y22) -> 0 | AB22: ='LPLPO GUDANG'!H27 -> 0 | BM22: =SUM(AH22:BL22) -> 0 | CT22: =SUM(BO22:CS22) -> 0 | EA22: =SUM(CV22:DZ22) -> 0 | FH22: =SUM(EC22:FG22) -> 0 | GO22: =SUM(FJ22:GN22) -> 0 | HV22: =SUM(GQ22:HU22) -> 0 | JC22: =SUM(HX22:JB22) -> 0 | KJ22: =SUM(JE22:KI22) -> 0
A23: =A22+1 -> 14 | B23: Asam askorbat (vitamin C) tab 250 mg | C23: Ktk @ 100 tablet | R23: =BM23 -> 0 | S23: =CT23 -> 0 | T23: =EA23 -> 0 | U23: =FH23 -> 0 | V23: =GO23 -> 0 | W23: =HV23 -> 0 | X23: =JC23 -> 0 | Y23: =KJ23 -> 0 | Z23: =SUM(D23:Y23) -> 0 | AB23: ='LPLPO GUDANG'!H28 -> 0 | BM23: =SUM(AH23:BL23) -> 0 | CT23: =SUM(BO23:CS23) -> 0 | EA23: =SUM(CV23:DZ23) -> 0 | FH23: =SUM(EC23:FG23) -> 0 | GO23: =SUM(FJ23:GN23) -> 0 | HV23: =SUM(GQ23:HU23) -> 0 | JC23: =SUM(HX23:JB23) -> 0 | KJ23: =SUM(JE23:KI23) -> 0
A24: =A23+1 -> 15 | B24: Asam askorbat (vitamin C) tab 50 mg | C24: Ktk @ 100 tablet | R24: =BM24 -> 0 | S24: =CT24 -> 0 | T24: =EA24 -> 0 | U24: =FH24 -> 0 | V24: =GO24 -> 0 | W24: =HV24 -> 0 | X24: =JC24 -> 0 | Y24: =KJ24 -> 0 | Z24: =SUM(D24:Y24) -> 0 | AB24: ='LPLPO GUDANG'!H29 -> 0 | BM24: =SUM(AH24:BL24) -> 0 | CT24: =SUM(BO24:CS24) -> 0 | EA24: =SUM(CV24:DZ24) -> 0 | FH24: =SUM(EC24:FG24) -> 0 | GO24: =SUM(FJ24:GN24) -> 0 | HV24: =SUM(GQ24:HU24) -> 0 | JC24: =SUM(HX24:JB24) -> 0 | KJ24: =SUM(JE24:KI24) -> 0
A25: =A24+1 -> 16 | B25: Asam mefenamat kaps 500 mg | C25: Ktk @ 100 tablet | I25: 100 | R25: =BM25 -> 1200 | S25: =CT25 -> 0 | T25: =EA25 -> 200 | U25: =FH25 -> 0 | V25: =GO25 -> 0 | W25: =HV25 -> 0 | X25: =JC25 -> 0 | Y25: =KJ25 -> 0 | Z25: =SUM(D25:Y25) -> 1500 | AB25: ='LPLPO GUDANG'!H30 -> 1000 | BE25: 1200 | BM25: =SUM(AH25:BL25) -> 1200 | CT25: =SUM(BO25:CS25) -> 0 | CX25: 200 | EA25: =SUM(CV25:DZ25) -> 200 | FH25: =SUM(EC25:FG25) -> 0 | GO25: =SUM(FJ25:GN25) -> 0 | HV25: =SUM(GQ25:HU25) -> 0 | JC25: =SUM(HX25:JB25) -> 0 | KJ25: =SUM(JE25:KI25) -> 0
A26: =A25+1 -> 17 | B26: Asam traneksamat inj 50 mg/ml | C26: Ampul | R26: =BM26 -> 0 | S26: =CT26 -> 0 | T26: =EA26 -> 0 | U26: =FH26 -> 0 | V26: =GO26 -> 0 | W26: =HV26 -> 0 | X26: =JC26 -> 0 | Y26: =KJ26 -> 0 | Z26: =SUM(D26:Y26) -> 0 | AB26: ='LPLPO GUDANG'!H31 -> 0 | BM26: =SUM(AH26:BL26) -> 0 | CT26: =SUM(BO26:CS26) -> 0 | EA26: =SUM(CV26:DZ26) -> 0 | FH26: =SUM(EC26:FG26) -> 0 | GO26: =SUM(FJ26:GN26) -> 0 | HV26: =SUM(GQ26:HU26) -> 0 | JC26: =SUM(HX26:JB26) -> 0 | KJ26: =SUM(JE26:KI26) -> 0
A27: =A26+1 -> 18 | B27: Asiklovir Krim | C27: tube | R27: =BM27 -> 0 | S27: =CT27 -> 0 | T27: =EA27 -> 0 | U27: =FH27 -> 0 | V27: =GO27 -> 0 | W27: =HV27 -> 0 | X27: =JC27 -> 0 | Y27: =KJ27 -> 0 | Z27: =SUM(D27:Y27) -> 0 | AB27: ='LPLPO GUDANG'!H32 -> 25 | BM27: =SUM(AH27:BL27) -> 0 | CT27: =SUM(BO27:CS27) -> 0 | EA27: =SUM(CV27:DZ27) -> 0 | FH27: =SUM(EC27:FG27) -> 0 | GO27: =SUM(FJ27:GN27) -> 0 | HV27: =SUM(GQ27:HU27) -> 0 | JC27: =SUM(HX27:JB27) -> 0 | KJ27: =SUM(JE27:KI27) -> 0
A28: =A27+1 -> 19 | B28: Asiklovir tab 400 mg | C28: Ktk 5 x 10 Tablet | R28: =BM28 -> 0 | S28: =CT28 -> 0 | T28: =EA28 -> 0 | U28: =FH28 -> 0 | V28: =GO28 -> 0 | W28: =HV28 -> 0 | X28: =JC28 -> 0 | Y28: =KJ28 -> 0 | Z28: =SUM(D28:Y28) -> 0 | AB28: ='LPLPO GUDANG'!H33 -> 1000 | BM28: =SUM(AH28:BL28) -> 0 | CT28: =SUM(BO28:CS28) -> 0 | EA28: =SUM(CV28:DZ28) -> 0 | FH28: =SUM(EC28:FG28) -> 0 | GO28: =SUM(FJ28:GN28) -> 0 | HV28: =SUM(GQ28:HU28) -> 0 | JC28: =SUM(HX28:JB28) -> 0 | KJ28: =SUM(JE28:KI28) -> 0
A29: =A28+1 -> 20 | B29: Atapulgit ( New Antides ) tab 600 mg | C29: Ktk 150 Tablet | R29: =BM29 -> 0 | S29: =CT29 -> 0 | T29: =EA29 -> 0 | U29: =FH29 -> 0 | V29: =GO29 -> 0 | W29: =HV29 -> 0 | X29: =JC29 -> 0 | Y29: =KJ29 -> 0 | Z29: =SUM(D29:Y29) -> 0 | AB29: ='LPLPO GUDANG'!H34 -> 800 | BM29: =SUM(AH29:BL29) -> 0 | CT29: =SUM(BO29:CS29) -> 0 | EA29: =SUM(CV29:DZ29) -> 0 | FH29: =SUM(EC29:FG29) -> 0 | GO29: =SUM(FJ29:GN29) -> 0 | HV29: =SUM(GQ29:HU29) -> 0 | JC29: =SUM(HX29:JB29) -> 0 | KJ29: =SUM(JE29:KI29) -> 0
A30: =A29+1 -> 21 | B30: Atorvastatin tab 20 mg | R30: =BM30 -> 0 | S30: =CT30 -> 0 | T30: =EA30 -> 0 | U30: =FH30 -> 0 | V30: =GO30 -> 0 | W30: =HV30 -> 0 | X30: =JC30 -> 0 | Y30: =KJ30 -> 0 | Z30: =SUM(D30:Y30) -> 0 | AB30: ='LPLPO GUDANG'!H35 -> 3000 | BM30: =SUM(AH30:BL30) -> 0 | CT30: =SUM(BO30:CS30) -> 0 | EA30: =SUM(CV30:DZ30) -> 0 | FH30: =SUM(EC30:FG30) -> 0 | GO30: =SUM(FJ30:GN30) -> 0 | HV30: =SUM(GQ30:HU30) -> 0 | JC30: =SUM(HX30:JB30) -> 0 | KJ30: =SUM(JE30:KI30) -> 0
A31: =A30+1 -> 22 | B31: Atropin inj 0,25 mg/ml (i.m./i.v./s.k) | C31: Ampul | R31: =BM31 -> 0 | S31: =CT31 -> 0 | T31: =EA31 -> 0 | U31: =FH31 -> 0 | V31: =GO31 -> 0 | W31: =HV31 -> 0 | X31: =JC31 -> 0 | Y31: =KJ31 -> 0 | Z31: =SUM(D31:Y31) -> 0 | AB31: ='LPLPO GUDANG'!H36 -> 0 | BM31: =SUM(AH31:BL31) -> 0 | CT31: =SUM(BO31:CS31) -> 0 | EA31: =SUM(CV31:DZ31) -> 0 | FH31: =SUM(EC31:FG31) -> 0 | GO31: =SUM(FJ31:GN31) -> 0 | HV31: =SUM(GQ31:HU31) -> 0 | JC31: =SUM(HX31:JB31) -> 0 | KJ31: =SUM(JE31:KI31) -> 0
A32: =A31+1 -> 23 | B32: Bedak Salicyl 2 % 60 gr | C32: Pot | R32: =BM32 -> 0 | S32: =CT32 -> 0 | T32: =EA32 -> 0 | U32: =FH32 -> 0 | V32: =GO32 -> 0 | W32: =HV32 -> 0 | X32: =JC32 -> 0 | Y32: =KJ32 -> 0 | Z32: =SUM(D32:Y32) -> 0 | AB32: ='LPLPO GUDANG'!H37 -> 0 | BM32: =SUM(AH32:BL32) -> 0 | CT32: =SUM(BO32:CS32) -> 0 | EA32: =SUM(CV32:DZ32) -> 0 | FH32: =SUM(EC32:FG32) -> 0 | GO32: =SUM(FJ32:GN32) -> 0 | HV32: =SUM(GQ32:HU32) -> 0 | JC32: =SUM(HX32:JB32) -> 0 | KJ32: =SUM(JE32:KI32) -> 0
A33: =A32+1 -> 24 | B33: Betahistin Mesilat tab 6 mg | C33: Ktk 10 x 10 tablet | R33: =BM33 -> 900 | S33: =CT33 -> 0 | T33: =EA33 -> 100 | U33: =FH33 -> 0 | V33: =GO33 -> 0 | W33: =HV33 -> 0 | X33: =JC33 -> 0 | Y33: =KJ33 -> 0 | Z33: =SUM(D33:Y33) -> 1000 | AB33: ='LPLPO GUDANG'!H38 -> 0 | AJ33: 500 | BF33: 400 | BM33: =SUM(AH33:BL33) -> 900 | CT33: =SUM(BO33:CS33) -> 0 | DL33: 100 | EA33: =SUM(CV33:DZ33) -> 100 | FH33: =SUM(EC33:FG33) -> 0 | GO33: =SUM(FJ33:GN33) -> 0 | HV33: =SUM(GQ33:HU33) -> 0 | JC33: =SUM(HX33:JB33) -> 0 | KJ33: =SUM(JE33:KI33) -> 0
A34: =A33+1 -> 25 | B34: Betametason krim 0,1% | C34: tube @ 5 gram | K34: 5 | R34: =BM34 -> 0 | S34: =CT34 -> 5 | T34: =EA34 -> 0 | U34: =FH34 -> 0 | V34: =GO34 -> 0 | W34: =HV34 -> 0 | X34: =JC34 -> 0 | Y34: =KJ34 -> 0 | Z34: =SUM(D34:Y34) -> 10 | AB34: ='LPLPO GUDANG'!H39 -> 60 | AC34: -2 | BM34: =SUM(AH34:BL34) -> 0 | CI34: 5 | CT34: =SUM(BO34:CS34) -> 5 | EA34: =SUM(CV34:DZ34) -> 0 | FH34: =SUM(EC34:FG34) -> 0 | GO34: =SUM(FJ34:GN34) -> 0 | HV34: =SUM(GQ34:HU34) -> 0 | JC34: =SUM(HX34:JB34) -> 0 | KJ34: =SUM(JE34:KI34) -> 0
A35: =A34+1 -> 26 | B35: Bisakodil sup 10 mg ( Dulcolax ) | C35: Suppositoria | R35: =BM35 -> 0 | S35: =CT35 -> 0 | T35: =EA35 -> 0 | U35: =FH35 -> 0 | V35: =GO35 -> 0 | W35: =HV35 -> 0 | X35: =JC35 -> 0 | Y35: =KJ35 -> 0 | Z35: =SUM(D35:Y35) -> 0 | AB35: ='LPLPO GUDANG'!H40 -> 0 | BM35: =SUM(AH35:BL35) -> 0 | CT35: =SUM(BO35:CS35) -> 0 | EA35: =SUM(CV35:DZ35) -> 0 | FH35: =SUM(EC35:FG35) -> 0 | GO35: =SUM(FJ35:GN35) -> 0 | HV35: =SUM(GQ35:HU35) -> 0 | JC35: =SUM(HX35:JB35) -> 0 | KJ35: =SUM(JE35:KI35) -> 0
A36: =A35+1 -> 27 | B36: Bisakodil sup 5 mg ( Dulcolax ) | C36: Suppositoria | R36: =BM36 -> 0 | S36: =CT36 -> 0 | T36: =EA36 -> 0 | U36: =FH36 -> 0 | V36: =GO36 -> 0 | W36: =HV36 -> 0 | X36: =JC36 -> 0 | Y36: =KJ36 -> 0 | Z36: =SUM(D36:Y36) -> 0 | AB36: ='LPLPO GUDANG'!H41 -> 0 | BM36: =SUM(AH36:BL36) -> 0 | CT36: =SUM(BO36:CS36) -> 0 | EA36: =SUM(CV36:DZ36) -> 0 | FH36: =SUM(EC36:FG36) -> 0 | GO36: =SUM(FJ36:GN36) -> 0 | HV36: =SUM(GQ36:HU36) -> 0 | JC36: =SUM(HX36:JB36) -> 0 | KJ36: =SUM(JE36:KI36) -> 0
A37: =A36+1 -> 28 | B37: Colcitin 0.5 gr | C37: Ktk 30 tab | R37: =BM37 -> 0 | S37: =CT37 -> 0 | T37: =EA37 -> 0 | U37: =FH37 -> 0 | V37: =GO37 -> 0 | W37: =HV37 -> 0 | X37: =JC37 -> 0 | Y37: =KJ37 -> 0 | Z37: =SUM(D37:Y37) -> 0 | AB37: ='LPLPO GUDANG'!H42 -> 0 | BM37: =SUM(AH37:BL37) -> 0 | CT37: =SUM(BO37:CS37) -> 0 | EA37: =SUM(CV37:DZ37) -> 0 | FH37: =SUM(EC37:FG37) -> 0 | GO37: =SUM(FJ37:GN37) -> 0 | HV37: =SUM(GQ37:HU37) -> 0 | JC37: =SUM(HX37:JB37) -> 0 | KJ37: =SUM(JE37:KI37) -> 0
A38: =A37+1 -> 29 | B38: Deksametason tab 0,5 mg | C38: Ktk @ 100 tablet | R38: =BM38 -> 2500 | S38: =CT38 -> 0 | T38: =EA38 -> 0 | U38: =FH38 -> 0 | V38: =GO38 -> 0 | W38: =HV38 -> 0 | X38: =JC38 -> 0 | Y38: =KJ38 -> 0 | Z38: =SUM(D38:Y38) -> 2500 | AB38: ='LPLPO GUDANG'!H43 -> 0 | AC38: -100 | AI38: 1000 | AZ38: 1000 | BF38: 500 | BM38: =SUM(AH38:BL38) -> 2500 | CT38: =SUM(BO38:CS38) -> 0 | EA38: =SUM(CV38:DZ38) -> 0 | FH38: =SUM(EC38:FG38) -> 0 | GO38: =SUM(FJ38:GN38) -> 0 | HV38: =SUM(GQ38:HU38) -> 0 | JC38: =SUM(HX38:JB38) -> 0 | KJ38: =SUM(JE38:KI38) -> 0
A39: =A38+1 -> 30 | B39: Deksametason inj 5 mg/ml (i.v./i.m.) | C39: Ampul | R39: =BM39 -> 0 | S39: =CT39 -> 0 | T39: =EA39 -> 0 | U39: =FH39 -> 0 | V39: =GO39 -> 0 | W39: =HV39 -> 0 | X39: =JC39 -> 0 | Y39: =KJ39 -> 0 | Z39: =SUM(D39:Y39) -> 0 | AB39: ='LPLPO GUDANG'!H44 -> 100 | BM39: =SUM(AH39:BL39) -> 0 | CT39: =SUM(BO39:CS39) -> 0 | EA39: =SUM(CV39:DZ39) -> 0 | FH39: =SUM(EC39:FG39) -> 0 | GO39: =SUM(FJ39:GN39) -> 0 | HV39: =SUM(GQ39:HU39) -> 0 | JC39: =SUM(HX39:JB39) -> 0 | KJ39: =SUM(JE39:KI39) -> 0
A40: =A39+1 -> 31 | B40: Dextrose 40% | C40: Botol | R40: =BM40 -> 0 | S40: =CT40 -> 0 | T40: =EA40 -> 0 | U40: =FH40 -> 0 | V40: =GO40 -> 0 | W40: =HV40 -> 0 | X40: =JC40 -> 0 | Y40: =KJ40 -> 0 | Z40: =SUM(D40:Y40) -> 0 | AB40: ='LPLPO GUDANG'!H45 -> 0 | BM40: =SUM(AH40:BL40) -> 0 | CT40: =SUM(BO40:CS40) -> 0 | EA40: =SUM(CV40:DZ40) -> 0 | FH40: =SUM(EC40:FG40) -> 0 | GO40: =SUM(FJ40:GN40) -> 0 | HV40: =SUM(GQ40:HU40) -> 0 | JC40: =SUM(HX40:JB40) -> 0 | KJ40: =SUM(JE40:KI40) -> 0
A41: =A40+1 -> 32 | B41: Diazepam inj 10 mg/ 2 ml ( i v./i.m .) stesolid | C41: Ampul @ 2 ml | R41: =BM41 -> 0 | S41: =CT41 -> 0 | T41: =EA41 -> 0 | U41: =FH41 -> 0 | V41: =GO41 -> 0 | W41: =HV41 -> 0 | X41: =JC41 -> 0 | Y41: =KJ41 -> 0 | Z41: =SUM(D41:Y41) -> 0 | AB41: ='LPLPO GUDANG'!H46 -> 5 | BM41: =SUM(AH41:BL41) -> 0 | CT41: =SUM(BO41:CS41) -> 0 | EA41: =SUM(CV41:DZ41) -> 0 | FH41: =SUM(EC41:FG41) -> 0 | GO41: =SUM(FJ41:GN41) -> 0 | HV41: =SUM(GQ41:HU41) -> 0 | JC41: =SUM(HX41:JB41) -> 0 | KJ41: =SUM(JE41:KI41) -> 0
...

Sheet STOK OPNAME GUDANG
A1: LAMPIRAN BERITA ACARA STOK OPNAME OBAT PKD
A2: UPT PUSKESMAS SUKAMAJU
A4: BULAN JANUARI TAHUN 2026
A5: NO | B5: Nama Obat | C5: SATUAN | D5: SISA STOK 31 JANUARI 2026
A7: 1 | B7: 2 | C7: 3 | D7: 4
A8: 1 | B8: Air untuk injeksi amp 25 ml | C8: Ampul | D8: ='LPLPO GUDANG'!H15 -> 0
A9: =A8+1 -> 2 | B9: Alopurinol tab 300 mg | C9: Ktk @ 100 tablet | D9: ='LPLPO GUDANG'!H16 -> 500
A10: =A9+1 -> 3 | B10: Ambroxol Sirup | C10: Botol | D10: ='LPLPO GUDANG'!H17 -> 15
A11: =A10+1 -> 4 | B11: Amlodipin tab 5 mg | C11: Ktk 50 Tablet | D11: ='LPLPO GUDANG'!H18 -> 1800
A12: =A11+1 -> 5 | B12: Amlodipin Tablet 10 mg | C12: Tablet | D12: ='LPLPO GUDANG'!H19 -> 1800
A13: =A12+1 -> 6 | B13: Amoksisilin sirup kering 125 mg/5 ml | C13: Botol | D13: ='LPLPO GUDANG'!H20 -> 135
A14: =A13+1 -> 7 | B14: Amoksisilin tab 500 mg | C14: Ktk @100 kaplet | D14: ='LPLPO GUDANG'!H21 -> 3100
A15: =A14+1 -> 8 | B15: Anestetik lokal gigi kombinasi : lidokain hcl 2% + epinefrin 1 : 80.000 inj 2 ml | C15: Ampul | D15: ='LPLPO GUDANG'!H22 -> 0
A16: =A15+1 -> 9 | B16: Antasida, kombinasi : aluminium hidroksida 200 mg + magnesium hidroksida 200 mg | C16: Btl 60 ml | D16: ='LPLPO GUDANG'!H23 -> 80
A17: =A16+1 -> 10 | B17: Antasida, kombinasi : aluminium hidroksida 200 mg + magnesium hidroksida 200 mg | C17: Ktk @ 100 tablet | D17: ='LPLPO GUDANG'!H24 -> 1900
A18: =A17+1 -> 11 | B18: Anti Tetanus Serum ( ATS ) 1500 IU | C18: Ampul | D18: ='LPLPO GUDANG'!H25 -> 0
A19: =A18+1 -> 12 | B19: Antihemoroid, kombinasi: bismut subgalat 150 mg + heksaklorofen 2,5 mg + lidokain lidokain 10 mg+ seng oksida 120 mg + sup ad 2 g | C19: Suppositoria | D19: ='LPLPO GUDANG'!H26 -> 20
A20: =A19+1 -> 13 | B20: Asam asetilsalisilat tab 80 mg (Miniaspi) | C20: Ktk @ 100 tablet | D20: ='LPLPO GUDANG'!H27 -> 0
... A123: =A122+1 -> 116 | B123: Siprofloksasin tab scored 500 mg | C123: Ktk @ 100 tablet | D123: ='LPLPO GUDANG'!H130 -> 900
A124: =A123+1 -> 117 | B124: Susu SGM Gain Optigrow | D124: ='LPLPO GUDANG'!H131 -> 0
A125: =A124+1 -> 118 | B125: Tiamin (vitamin B1) tab 50 mg | C125: Ktk @ 100 tablet | D125: ='LPLPO GUDANG'!H132 -> 2700
A126: =A125+1 -> 119 | B126: Triheksifenidil Tablet 2 mg | C126: Ktk 10 x 10 Tab | D126: ='LPLPO GUDANG'!H133 -> 0
A127: =A126+1 -> 120 | B127: Vitamin B kompleks tablet | C127: Ktk @ 100 tablet | D127: ='LPLPO GUDANG'!H134 -> 0
A128: =A127+1 -> 121 | B128: Zinc tab disp 20 mg | C128: Ktk @ 100 tablet | D128: ='LPLPO GUDANG'!H135 -> 0
A129: =A128+1 -> 122 | B129: Zinc sirup | C129: Botol | D129: ='LPLPO GUDANG'!H136 -> 80
A130: =A129+1 -> 123 | B130: Alat suntik sekali pakai 1 ml | C130: Pcs | D130: ='LPLPO GUDANG'!H137 -> 80
A131: =A130+1 -> 124 | B131: Alat suntik sekali pakai 1 ml | C131: Pcs | D131: ='LPLPO GUDANG'!H138 -> 0
A132: =A131+1 -> 125 | B132: Alat suntik sekali pakai 10 ml | C132: Pcs | D132: ='LPLPO GUDANG'!H139 -> 0
A133: =A132+1 -> 126 | B133: Alat suntik sekali pakai 3 ml | C133: Pcs | D133: ='LPLPO GUDANG'!H140 -> 265
A134: =A133+1 -> 127 | B134: Alat suntik sekali pakai 3 ml | C134: Pcs | D134: ='LPLPO GUDANG'!H141 -> 0
A135: =A134+1 -> 128 | B135: Alat suntik sekali pakai 5 ml | C135: Pcs | D135: ='LPLPO GUDANG'!H142 -> 0
A136: =A135+1 -> 129 | B136: Alkohol SWAB | C136: Pcs | D136: ='LPLPO GUDANG'!H143 -> 2000
... A138: =A137+1 -> 131 | B138: Asering larutan infus | C138: Botol | D138: ='LPLPO GUDANG'!H145 -> 0
A139: =A138+1 -> 132 | B139: Cartridge | D139: ='LPLPO GUDANG'!H146 -> 0
A140: =A139+1 -> 133 | B140: Catgut / Benang Bedah No.2/0-3/0 | C140: Pcs | D140: ='LPLPO GUDANG'!H147 -> 0
A141: =A140+1 -> 134 | B141: Etakridin larutan 0,1% | C141: Botol | D141: ='LPLPO GUDANG'!H148 -> 4
A142: =A141+1 -> 135 | B142: Etanol ( Alkohol ) 70% | C142: Botol | D142: ='LPLPO GUDANG'!H149 -> 0
A143: =A142+1 -> 136 | B143: Folley Catheter No. 16 | C143: Pcs | D143: ='LPLPO GUDANG'!H150 -> 15
A144: =A143+1 -> 137 | B144: Folley Catheter No. 18 | C144: Pcs | D144: ='LPLPO GUDANG'!H151 -> 10
A145: =A144+1 -> 138 | B145: Infus Set Dewasa | C145: Pcs | D145: ='LPLPO GUDANG'!H152 -> 50
...

Sheet STOK OPNAME PROGRAM
A1: LAMPIRAN BERITA ACARA STOK OPNAME OBAT PROGRAM
A2: UPT PUSKESMAS SUKAMAJU
A4: ='STOK OPNAME GUDANG'!A4 -> BULAN JANUARI TAHUN 2026
A5: NO | B5: Nama Obat | C5: SATUAN | D5: ='STOK OPNAME GUDANG'!D5:D6 -> SISA STOK 31 JANUARI 2026
A7: 1 | B7: 2 | C7: 3 | D7: 4
A8: 1 | B8: GIZI
A9: 2 | B9: Mineral Mix | C9: Sacshet | D9: ='LPLPO PROGRAM'!H15 -> 0
A10: 3 | B10: Supralysin | C10: Botol | D10: ='LPLPO PROGRAM'!H16 -> 0
A11: 4 | B11: Tabelt Tambah Darah | C11: Tablet | D11: ='LPLPO PROGRAM'!H17 -> 20000
A12: 5 | B12: Taburia | C12: Sacshet | D12: ='LPLPO PROGRAM'!H18 -> 0
A13: 6 | B13: Vitamin A Biru 10000 iu | C13: Kapsul | D13: ='LPLPO PROGRAM'!H19 -> 0
A14: 7 | B14: Vitamin A Merah 20000 iu | C14: Kapsul | D14: ='LPLPO PROGRAM'!H20 -> 50
A15: 8 | D15: ='LPLPO PROGRAM'!H21 -> 0
A16: 9 | D16: ='LPLPO PROGRAM'!H22 -> 0
A17: 10 | D17: ='LPLPO PROGRAM'!H23 -> 0
A18: 11 | B18: OBAT KESEHATAN IBU ANAK
A19: 12 | B19: Phenobarbital Injeksi | C19: Ampul | D19: ='LPLPO PROGRAM'!H25 -> 0
A20: 13 | B20: Ampicilin injeksi | C20: vial | D20: ='LPLPO PROGRAM'!H26 -> 0
A21: 14 | B21: Calsii Gluconas | C21: Ampul | D21: ='LPLPO PROGRAM'!H27 -> 0
A22: 15 | B22: Dextrosa 5% | C22: Botol | D22: ='LPLPO PROGRAM'!H28 -> 0
A23: 16 | B23: Diazepam Injeksi | C23: Ampul | D23: ='LPLPO PROGRAM'!H29 -> 0
A24: 17 | B24: Fitomenadion injeksi 2 mg/ ml | C24: Ampul | D24: ='LPLPO PROGRAM'!H30 -> 0
A25: 18 | B25: Methyl Ergometrine inje 2 mg | C25: Ampul | D25: ='LPLPO PROGRAM'!H31 -> 0
A26: 19 | B26: Mgso4 20 % | C26: Ampul | D26: ='LPLPO PROGRAM'!H32 -> 0
A27: 20 | B27: Mgso4 40 % | C27: Ampul | D27: ='LPLPO PROGRAM'!H33 -> 0
A28: 21 | B28: Oksitosin Injeksi | C28: Ampul | D28: ='LPLPO PROGRAM'!H34 -> 10
A29: 22 | B29: Oxytetra Salep mata 1 % | C29: Tube | D29: ='LPLPO PROGRAM'!H35 -> 0
A30: 23 | B30: Proten Gold Vanila | D30: ='LPLPO PROGRAM'!H36 -> 0
A31: 24 | B31: Levothyrokxine | C31: Tablet | D31: ='LPLPO PROGRAM'!H37 -> 0
A32: 25 | B32: Multivitamin MMS | C32: Botol | D32: ='LPLPO PROGRAM'!H38 -> 362
A33: 26 | B33: Kloramfenikol Salep Mata | C33: Tube | D33: ='LPLPO PROGRAM'!H39 -> 0
A34: 27 | D34: ='LPLPO PROGRAM'!H40 -> 0
A35: 28 | B35: OBAT PROGRAM MALARIA
A36: 29 | B36: ACT ( Obat Antimalaria )/DHP | C36: Tablet | D36: ='LPLPO PROGRAM'!H42 -> 0
A37: 30 | B37: Artesunat Injeksi 60mg/ml | C37: vial | D37: ='LPLPO PROGRAM'!H43 -> 0
A38: 31 | B38: Giemsa | C38: Botol | D38: ='LPLPO PROGRAM'!H44 -> 0
A39: 32 | B39: Primaquin | C39: Tablet | D39: ='LPLPO PROGRAM'!H45 -> 0
A40: 33 | B40: RDT Chikungunya | C40: Pcs | D40: ='LPLPO PROGRAM'!H46 -> 0
A41: 34 | B41: RDT DBD | C41: Pcs | D41: ='LPLPO PROGRAM'!H47 -> 0
A42: 35 | B42: RDT Frambusia | C42: Pcs | D42: ='LPLPO PROGRAM'!H48 -> 0
...

Sheet LPLPO GUDANG
A1: LAPORAN PEMAKAIAN DAN LEMBAR PERMINTAAN OBAT
A2: (LPLPO)
A4: KODE PUSKESMAS | C4: : LPLPO GUDANG
A5: PUSKESMAS | C5: : SUKAMAJU
A6: KECAMATAN | C6: : SUKAMAJU
A7: KABUPATEN | C7: : LUWU UTARA
A8: PROPINSI | C8: : SULAWESI SELATAN
K9: BULAN | M9: : FEBRUARI
K10: TAHUN | M10: : 2026
A12: NO | B12: NAMA OBAT | C12: SATUAN | D12: STOK AWAL | E12: PENERIMAAN | F12: PERSEDIAAN | G12: PEMAKAIAN | H12: SISA STOK | I12: PERMINTAAN | J12: PEMBERIAN | O12: KET
J13: PKD | K13: JKN | L13: PROG | M13: LAIN-LAIN | N13: JML
A14: 1 | B14: 2 | C14: 3 | D14: 5 | E14: 6 | F14: 7 | G14: 8 | H14: 9 | I14: 10 | J14: 11 | K14: 12 | L14: 13 | M14: 14 | N14: 15 | O14: 16
A15: 1 | B15: Air untuk injeksi amp 25 ml | C15: Ampul | D15: 30 | E15: ='PENERIMAAN OBAT PKD'!H9 -> 30 | F15: =SUM(D15:E15) -> 60 | G15: =DISTRIBUSI!Z10 -> 60 | H15: =F15-G15 -> 0 | I15: 200 | J15: ='STOK OPNAME GUDANG'!D8 -> 0 | L15: =E15-K15 -> 30 | M15: =DISTRIBUSI!Z10 -> 60 | N15: =G15-M15 -> 0
A16: =A15+1 -> 2 | B16: Alopurinol tab 300 mg | C16: Ktk @ 100 tablet | D16: 500 | E16: ='PENERIMAAN OBAT PKD'!H10 -> 500 | F16: =SUM(D16:E16) -> 1000 | G16: =DISTRIBUSI!Z11 -> 500 | H16: =F16-G16 -> 500 | I16: 1000 | J16: ='STOK OPNAME GUDANG'!D9 -> 500 | L16: =E16-K16 -> 500 | M16: =DISTRIBUSI!Z11 -> 500 | N16: =G16-M16 -> 0
A17: =A16+1 -> 3 | B17: Ambroxol Sirup | C17: Botol | D17: 45 | E17: ='PENERIMAAN OBAT PKD'!H11 -> 0 | F17: =SUM(D17:E17) -> 45 | G17: =DISTRIBUSI!Z12 -> 30 | H17: =F17-G17 -> 15 | I17: 50 | J17: ='STOK OPNAME GUDANG'!D10 -> 15 | L17: =E17-K17 -> 0 | M17: =DISTRIBUSI!Z12 -> 30 | N17: =G17-M17 -> 0
A18: =A17+1 -> 4 | B18: Amlodipin tab 5 mg | C18: Ktk 50 Tablet | D18: 2000 | E18: ='PENERIMAAN OBAT PKD'!H12 -> 2000 | F18: =SUM(D18:E18) -> 4000 | G18: =DISTRIBUSI!Z13 -> 2200 | H18: =F18-G18 -> 1800 | I18: 3000 | J18: ='STOK OPNAME GUDANG'!D11 -> 1800 | L18: =E18-K18 -> 2000 | M18: =DISTRIBUSI!Z13 -> 2200 | N18: =G18-M18 -> 0
A19: =A18+1 -> 5 | B19: Amlodipin Tablet 10 mg | C19: Tablet | D19: 2000 | E19: ='PENERIMAAN OBAT PKD'!H13 -> 3000 | F19: =SUM(D19:E19) -> 5000 | G19: =DISTRIBUSI!Z14 -> 3200 | H19: =F19-G19 -> 1800 | I19: 3000 | J19: ='STOK OPNAME GUDANG'!D12 -> 1800 | L19: =E19-K19 -> 3000 | M19: =DISTRIBUSI!Z14 -> 3200 | N19: =G19-M19 -> 0
A20: =A19+1 -> 6 | B20: Amoksisilin sirup kering 125 mg/5 ml | C20: Botol | D20: 135 | E20: ='PENERIMAAN OBAT PKD'!H14 -> 0 | F20: =SUM(D20:E20) -> 135 | G20: =DISTRIBUSI!Z15 -> 0 | H20: =F20-G20 -> 135 | J20: ='STOK OPNAME GUDANG'!D13 -> 135 | L20: =E20-K20 -> 0 | M20: =DISTRIBUSI!Z15 -> 0 | N20: =G20-M20 -> 0
A21: =A20+1 -> 7 | B21: Amoksisilin tab 500 mg | C21: Ktk @100 kaplet | D21: 2000 | E21: ='PENERIMAAN OBAT PKD'!H15 -> 1500 | F21: =SUM(D21:E21) -> 3500 | G21: =DISTRIBUSI!Z16 -> 400 | H21: =F21-G21 -> 3100 | J21: ='STOK OPNAME GUDANG'!D14 -> 3100 | L21: =E21-K21 -> 1500 | M21: =DISTRIBUSI!Z16 -> 400 | N21: =G21-M21 -> 0
A22: =A21+1 -> 8 | B22: Anestetik lokal gigi kombinasi : lidokain hcl 2% + epinefrin 1 : 80.000 inj 2 ml | C22: Ampul | D22: 0 | E22: ='PENERIMAAN OBAT PKD'!H16 -> 100 | F22: =SUM(D22:E22) -> 100 | G22: =DISTRIBUSI!Z17 -> 100 | H22: =F22-G22 -> 0 | I22: 200 | J22: ='STOK OPNAME GUDANG'!D15 -> 0 | L22: =E22-K22 -> 100 | M22: =DISTRIBUSI!Z17 -> 100 | N22: =G22-M22 -> 0
A23: =A22+1 -> 9 | B23: Antasida, kombinasi : aluminium hidroksida 200 mg + magnesium hidroksida 200 mg | C23: Btl 60 ml | D23: 90 | E23: ='PENERIMAAN OBAT PKD'!H17 -> 50 | F23: =SUM(D23:E23) -> 140 | G23: =DISTRIBUSI!Z18 -> 60 | H23: =F23-G23 -> 80 | I23: 100 | J23: ='STOK OPNAME GUDANG'!D16 -> 80 | L23: =E23-K23 -> 50 | M23: =DISTRIBUSI!Z18 -> 60 | N23: =G23-M23 -> 0
A24: =A23+1 -> 10 | B24: Antasida, kombinasi : aluminium hidroksida 200 mg + magnesium hidroksida 200 mg | C24: Ktk @ 100 tablet | D24: 1400 | E24: ='PENERIMAAN OBAT PKD'!H18 -> 1000 | F24: =SUM(D24:E24) -> 2400 | G24: =DISTRIBUSI!Z19 -> 500 | H24: =F24-G24 -> 1900 | I24: 1000 | J24: ='STOK OPNAME GUDANG'!D17 -> 1900 | L24: =E24-K24 -> 1000 | M24: =DISTRIBUSI!Z19 -> 500 | N24: =G24-M24 -> 0
A25: =A24+1 -> 11 | B25: Anti Tetanus Serum ( ATS ) 1500 IU | C25: Ampul | E25: ='PENERIMAAN OBAT PKD'!H19 -> 0 | F25: =SUM(D25:E25) -> 0 | G25: =DISTRIBUSI!Z20 -> 0 | H25: =F25-G25 -> 0 | J25: ='STOK OPNAME GUDANG'!D18 -> 0 | L25: =E25-K25 -> 0 | M25: =DISTRIBUSI!Z20 -> 0 | N25: =G25-M25 -> 0
A26: =A25+1 -> 12 | B26: Antihemoroid, kombinasi: bismut subgalat 150 mg + heksaklorofen 2,5 mg + lidokain lidokain 10 mg+ seng oksida 120 mg + sup ad 2 g | C26: Suppositoria | D26: 20 | E26: ='PENERIMAAN OBAT PKD'!H20 -> 0 | F26: =SUM(D26:E26) -> 20 | G26: =DISTRIBUSI!Z21 -> 0 | H26: =F26-G26 -> 20 | I26: 20 | J26: ='STOK OPNAME GUDANG'!D19 -> 20 | L26: =E26-K26 -> 0 | M26: =DISTRIBUSI!Z21 -> 0 | N26: =G26-M26 -> 0
A27: =A26+1 -> 13 | B27: Asam asetilsalisilat tab 80 mg (Miniaspi) | C27: Ktk @ 100 tablet | E27: ='PENERIMAAN OBAT PKD'!H21 -> 0 | F27: =SUM(D27:E27) -> 0 | G27: =DISTRIBUSI!Z22 -> 0 | H27: =F27-G27 -> 0 | J27: ='STOK OPNAME GUDANG'!D20 -> 0 | L27: =E27-K27 -> 0 | M27: =DISTRIBUSI!Z22 -> 0 | N27: =G27-M27 -> 0
A28: =A27+1 -> 14 | B28: Asam askorbat (vitamin C) tab 250 mg | C28: Ktk @ 100 tablet | E28: ='PENERIMAAN OBAT PKD'!H22 -> 0 | F28: =SUM(D28:E28) -> 0 | G28: =DISTRIBUSI!Z23 -> 0 | H28: =F28-G28 -> 0 | J28: ='STOK OPNAME GUDANG'!D21 -> 0 | L28: =E28-K28 -> 0 | M28: =DISTRIBUSI!Z23 -> 0 | N28: =G28-M28 -> 0
A29: =A28+1 -> 15 | B29: Asam askorbat (vitamin C) tab 50 mg | C29: Ktk @ 100 tablet | E29: ='PENERIMAAN OBAT PKD'!H23 -> 0 | F29: =SUM(D29:E29) -> 0 | G29: =DISTRIBUSI!Z24 -> 0 | H29: =F29-G29 -> 0 | J29: ='STOK OPNAME GUDANG'!D22 -> 0 | L29: =E29-K29 -> 0 | M29: =DISTRIBUSI!Z24 -> 0 | N29: =G29-M29 -> 0
A30: =A29+1 -> 16 | B30: Asam mefenamat kaps 500 mg | C30: Ktk @ 100 tablet | D30: 1000 | E30: ='PENERIMAAN OBAT PKD'!H24 -> 1500 | F30: =SUM(D30:E30) -> 2500 | G30: =DISTRIBUSI!Z25 -> 1500 | H30: =F30-G30 -> 1000 | I30: 2000 | J30: ='STOK OPNAME GUDANG'!D23 -> 1000 | L30: =E30-K30 -> 1500 | M30: =DISTRIBUSI!Z25 -> 1500 | N30: =G30-M30 -> 0
A31: =A30+1 -> 17 | B31: Asam traneksamat inj 50 mg/ml | C31: Ampul | E31: ='PENERIMAAN OBAT PKD'!H25 -> 0 | F31: =SUM(D31:E31) -> 0 | G31: =DISTRIBUSI!Z26 -> 0 | H31: =F31-G31 -> 0 | J31: ='STOK OPNAME GUDANG'!D24 -> 0 | L31: =E31-K31 -> 0 | M31: =DISTRIBUSI!Z26 -> 0 | N31: =G31-M31 -> 0
A32: =A31+1 -> 18 | B32: Asiklovir Krim | C32: tube | D32: 0 | E32: ='PENERIMAAN OBAT PKD'!H26 -> 25 | F32: =SUM(D32:E32) -> 25 | G32: =DISTRIBUSI!Z27 -> 0 | H32: =F32-G32 -> 25 | J32: ='STOK OPNAME GUDANG'!D25 -> 25 | L32: =E32-K32 -> 25 | M32: =DISTRIBUSI!Z27 -> 0 | N32: =G32-M32 -> 0
A33: =A32+1 -> 19 | B33: Asiklovir tab 400 mg | C33: Ktk 5 x 10 Tablet | D33: 1000 | E33: ='PENERIMAAN OBAT PKD'!H27 -> 0 | F33: =SUM(D33:E33) -> 1000 | G33: =DISTRIBUSI!Z28 -> 0 | H33: =F33-G33 -> 1000 | J33: ='STOK OPNAME GUDANG'!D26 -> 1000 | L33: =E33-K33 -> 0 | M33: =DISTRIBUSI!Z28 -> 0 | N33: =G33-M33 -> 0
A34: =A33+1 -> 20 | B34: Atapulgit ( New Antides ) tab 600 mg | C34: Ktk 150 Tablet | D34: 800 | E34: ='PENERIMAAN OBAT PKD'!H28 -> 0 | F34: =SUM(D34:E34) -> 800 | G34: =DISTRIBUSI!Z29 -> 0 | H34: =F34-G34 -> 800 | J34: ='STOK OPNAME GUDANG'!D27 -> 800 | L34: =E34-K34 -> 0 | M34: =DISTRIBUSI!Z29 -> 0 | N34: =G34-M34 -> 0
A35: =A34+1 -> 21 | B35: Atorvastatin tab | C35: Tablet | D35: 1000 | E35: ='PENERIMAAN OBAT PKD'!H29 -> 2000 | F35: =SUM(D35:E35) -> 3000 | G35: =DISTRIBUSI!Z30 -> 0 | H35: =F35-G35 -> 3000
A36: =A35+1 -> 22 | B36: Atropin inj 0,25 mg/ml (i.m./i.v./s.k) | C36: Ampul | E36: ='PENERIMAAN OBAT PKD'!H30 -> 0 | F36: =SUM(D36:E36) -> 0 | G36: =DISTRIBUSI!Z31 -> 0 | H36: =F36-G36 -> 0 | J36: ='STOK OPNAME GUDANG'!D28 -> 3000 | L36: =E36-K36 -> 0 | M36: =DISTRIBUSI!Z31 -> 0 | N36: =G36-M36 -> 0
A37: =A36+1 -> 23 | B37: Bedak Salicyl 2 % 60 gr | C37: Pot | E37: ='PENERIMAAN OBAT PKD'!H31 -> 0 | F37: =SUM(D37:E37) -> 0 | G37: =DISTRIBUSI!Z32 -> 0 | H37: =F37-G37 -> 0 | J37: ='STOK OPNAME GUDANG'!D29 -> 0 | L37: =E37-K37 -> 0 | M37: =DISTRIBUSI!Z32 -> 0 | N37: =G37-M37 -> 0
A38: =A37+1 -> 24 | B38: Betahistin Mesilat tab 6 mg | C38: Ktk 10 x 10 tablet | D38: 1000 | E38: ='PENERIMAAN OBAT PKD'!H32 -> 0 | F38: =SUM(D38:E38) -> 1000 | G38: =DISTRIBUSI!Z33 -> 1000 | H38: =F38-G38 -> 0 | I38: 1000 | J38: ='STOK OPNAME GUDANG'!D30 -> 0 | L38: =E38-K38 -> 0 | M38: =DISTRIBUSI!Z33 -> 1000 | N38: =G38-M38 -> 0
A39: =A38+1 -> 25 | B39: Betametason krim 0,1% | C39: tube @ 5 gram | D39: 70 | E39: ='PENERIMAAN OBAT PKD'!H33 -> 0 | F39: =SUM(D39:E39) -> 70 | G39: =DISTRIBUSI!Z34 -> 10 | H39: =F39-G39 -> 60 | J39: ='STOK OPNAME GUDANG'!D31 -> 0 | L39: =E39-K39 -> 0 | M39: =DISTRIBUSI!Z34 -> 10 | N39: =G39-M39 -> 0
A40: =A39+1 -> 26 | B40: Bisakodil sup 10 mg ( Dulcolax ) | C40: Suppositoria | E40: ='PENERIMAAN OBAT PKD'!H34 -> 0 | F40: =SUM(D40:E40) -> 0 | G40: =DISTRIBUSI!Z35 -> 0 | H40: =F40-G40 -> 0 | J40: ='STOK OPNAME GUDANG'!D32 -> 60 | L40: =E40-K40 -> 0 | M40: =DISTRIBUSI!Z35 -> 0 | N40: =G40-M40 -> 0
A41: =A40+1 -> 27 | B41: Bisakodil sup 5 mg ( Dulcolax ) | C41: Suppositoria | E41: ='PENERIMAAN OBAT PKD'!H35 -> 0 | F41: =SUM(D41:E41) -> 0 | G41: =DISTRIBUSI!Z36 -> 0 | H41: =F41-G41 -> 0 | J41: ='STOK OPNAME GUDANG'!D33 -> 0 | L41: =E41-K41 -> 0 | M41: =DISTRIBUSI!Z36 -> 0 | N41: =G41-M41 -> 0
A42: =A41+1 -> 28 | B42: Colcitin 0.5 gr | C42: Ktk 30 tab | E42: ='PENERIMAAN OBAT PKD'!H36 -> 0 | F42: =SUM(D42:E42) -> 0 | G42: =DISTRIBUSI!Z37 -> 0 | H42: =F42-G42 -> 0 | J42: ='STOK OPNAME GUDANG'!D34 -> 0 | L42: =E42-K42 -> 0 | M42: =DISTRIBUSI!Z37 -> 0 | N42: =G42-M42 -> 0
...

Sheet LPLPO PROGRAM
A1: LAPORAN PEMAKAIAN DAN LEMBAR PERMINTAAN OBAT
A2: (LPLPO)
A4: KODE PUSKESMAS | C4: : LPLPO PROGRAM
A5: PUSKESMAS | C5: : SUKAMAJU
A6: KECAMATAN | C6: : SUKAMAJU
A7: KABUPATEN | C7: : LUWU UTARA
A8: PROPINSI | C8: : SULAWESI SELATAN
K9: BULAN | M9: FEBRUARI
K10: TAHUN | M10: 2026 | W10: 12
A11: NO | B11: Nama Obat | C11: SATUAN | D11: STOK AWAL | E11: PENERIMAAN | F11: PERSEDIAAN | G11: PEMAKAIAN | H11: SISA STOK | I11: PERMINTAAN | J11: PEMBERIAN | O11: KET
J12: PKD | K12: JKN | L12: PROG | M12: LAIN-LAIN | N12: JML
A13: 1 | B13: 2 | C13: 4 | D13: 5 | E13: 6 | F13: 7 | G13: 8 | H13: 9 | I13: 10 | J13: 11 | K13: 12 | L13: 13 | M13: 14 | N13: 15 | O13: 16
A14: 1 | B14: GIZI
A15: 2 | B15: Mineral Mix | C15: Sacshet | E15: ='PENERIMAAN OBAT PROGRAM'!G10 -> 0 | F15: =D15+E15 -> 0 | G15: =DISTRIBUSI!Z184 -> 0 | H15: =F15-G15 -> 0 | R15: 0 | S15: =H15-R15 -> 0
A16: 3 | B16: Supralysin | C16: Botol | E16: ='PENERIMAAN OBAT PROGRAM'!G11 -> 0 | F16: =D16+E16 -> 0 | G16: =DISTRIBUSI!Z185 -> 0 | H16: =F16-G16 -> 0 | R16: 0 | S16: =H16-R16 -> 0
A17: 4 | B17: Tabelt Tambah Darah | C17: Tablet | D17: 4300 | E17: ='PENERIMAAN OBAT PROGRAM'!G12 -> 20000 | F17: =D17+E17 -> 24300 | G17: =DISTRIBUSI!Z186 -> 4300 | H17: =F17-G17 -> 20000 | R17: 2700 | S17: =H17-R17 -> 17300
A18: 5 | B18: Taburia | C18: Sacshet | E18: ='PENERIMAAN OBAT PROGRAM'!G13 -> 0 | F18: =D18+E18 -> 0 | G18: =DISTRIBUSI!Z187 -> 0 | H18: =F18-G18 -> 0 | R18: 0 | S18: =H18-R18 -> 0
A19: 6 | B19: Vitamin A Biru 10000 iu | C19: Kapsul | E19: ='PENERIMAAN OBAT PROGRAM'!G14 -> 0 | F19: =D19+E19 -> 0 | G19: =DISTRIBUSI!Z188 -> 0 | H19: =F19-G19 -> 0 | R19: 0 | S19: =H19-R19 -> 0
A20: 7 | B20: Vitamin A Merah 20000 iu | C20: Kapsul | D20: 50 | E20: ='PENERIMAAN OBAT PROGRAM'!G15 -> 0 | F20: =D20+E20 -> 50 | G20: =DISTRIBUSI!Z189 -> 0 | H20: =F20-G20 -> 50 | R20: 0 | S20: =H20-R20 -> 50
A21: 8 | E21: ='PENERIMAAN OBAT PROGRAM'!G16 -> 0 | F21: =D21+E21 -> 0 | G21: =DISTRIBUSI!Z190 -> 0 | H21: =F21-G21 -> 0 | R21: 0 | S21: =H21-R21 -> 0
A22: 9 | E22: ='PENERIMAAN OBAT PROGRAM'!G17 -> 0 | F22: =D22+E22 -> 0 | G22: =DISTRIBUSI!Z191 -> 0 | H22: =F22-G22 -> 0 | R22: 0 | S22: =H22-R22 -> 0
A23: 10 | E23: ='PENERIMAAN OBAT PROGRAM'!G18 -> 0 | F23: =D23+E23 -> 0 | G23: =DISTRIBUSI!Z192 -> 0 | H23: =F23-G23 -> 0 | R23: 0 | S23: =H23-R23 -> 0
A24: 11 | B24: OBAT KESEHATAN IBU ANAK | S24: =H24-R24 -> 0
A25: 12 | B25: Phenobarbital Injeksi | C25: Ampul | E25: ='PENERIMAAN OBAT PROGRAM'!G20 -> 0 | F25: =D25+E25 -> 0 | G25: =DISTRIBUSI!Z194 -> 0 | H25: =F25-G25 -> 0 | R25: 0 | S25: =H25-R25 -> 0
A26: 13 | B26: Ampicilin injeksi | C26: vial | E26: ='PENERIMAAN OBAT PROGRAM'!G21 -> 0 | F26: =D26+E26 -> 0 | G26: =DISTRIBUSI!Z195 -> 0 | H26: =F26-G26 -> 0 | R26: 0 | S26: =H26-R26 -> 0
A27: 14 | B27: Calsii Gluconas | C27: Ampul | E27: ='PENERIMAAN OBAT PROGRAM'!G22 -> 0 | F27: =D27+E27 -> 0 | G27: =DISTRIBUSI!Z196 -> 0 | H27: =F27-G27 -> 0 | R27: 0 | S27: =H27-R27 -> 0
A28: 15 | B28: Dextrosa 5% | C28: Botol | E28: ='PENERIMAAN OBAT PROGRAM'!G23 -> 0 | F28: =D28+E28 -> 0 | G28: =DISTRIBUSI!Z197 -> 0 | H28: =F28-G28 -> 0 | R28: 0 | S28: =H28-R28 -> 0
A29: 16 | B29: Diazepam Injeksi | C29: Ampul | E29: ='PENERIMAAN OBAT PROGRAM'!G24 -> 0 | F29: =D29+E29 -> 0 | G29: =DISTRIBUSI!Z198 -> 0 | H29: =F29-G29 -> 0 | R29: 0 | S29: =H29-R29 -> 0
A30: 17 | B30: Fitomenadion injeksi 2 mg/ ml | C30: Ampul | D30: 40 | E30: ='PENERIMAAN OBAT PROGRAM'!G25 -> 0 | F30: =D30+E30 -> 40 | G30: =DISTRIBUSI!Z199 -> 40 | H30: =F30-G30 -> 0 | R30: 0 | S30: =H30-R30 -> 0
A31: 18 | B31: Methyl Ergometrine inje 2 mg | C31: Ampul | E31: ='PENERIMAAN OBAT PROGRAM'!G26 -> 0 | F31: =D31+E31 -> 0 | G31: =DISTRIBUSI!Z200 -> 0 | H31: =F31-G31 -> 0 | R31: 0 | S31: =H31-R31 -> 0
A32: 19 | B32: Mgso4 20 % | C32: Ampul | E32: ='PENERIMAAN OBAT PROGRAM'!G27 -> 0 | F32: =D32+E32 -> 0 | G32: =DISTRIBUSI!Z201 -> 0 | H32: =F32-G32 -> 0 | R32: 0 | S32: =H32-R32 -> 0
A33: 20 | B33: Mgso4 40 % | C33: Ampul | E33: ='PENERIMAAN OBAT PROGRAM'!G28 -> 0 | F33: =D33+E33 -> 0 | G33: =DISTRIBUSI!Z202 -> 0 | H33: =F33-G33 -> 0 | R33: 0 | S33: =H33-R33 -> 0
A34: 21 | B34: Oksitosin Injeksi | C34: Ampul | E34: ='PENERIMAAN OBAT PROGRAM'!G29 -> 50 | F34: =D34+E34 -> 50 | G34: =DISTRIBUSI!Z203 -> 40 | H34: =F34-G34 -> 10 | R34: 0 | S34: =H34-R34 -> 10
A35: 22 | B35: Oxytetra Salep mata 1 % | C35: Tube | E35: ='PENERIMAAN OBAT PROGRAM'!G30 -> 0 | F35: =D35+E35 -> 0 | G35: =DISTRIBUSI!Z204 -> 0 | H35: =F35-G35 -> 0 | R35: 0 | S35: =H35-R35 -> 0
A36: 23 | B36: Proten Gold Vanila | E36: ='PENERIMAAN OBAT PROGRAM'!G31 -> 0 | F36: =D36+E36 -> 0 | G36: =DISTRIBUSI!Z205 -> 0 | H36: =F36-G36 -> 0 | R36: 0 | S36: =H36-R36 -> 0
A37: 24 | B37: Levothyrokxine | C37: Tablet | E37: ='PENERIMAAN OBAT PROGRAM'!G32 -> 0 | F37: =D37+E37 -> 0 | G37: =DISTRIBUSI!Z206 -> 0 | H37: =F37-G37 -> 0 | R37: 0 | S37: =H37-R37 -> 0
A38: 25 | B38: Multivitamin MMS | C38: Botol | E38: ='PENERIMAAN OBAT PROGRAM'!G33 -> 409 | F38: =D38+E38 -> 409 | G38: =DISTRIBUSI!Z207 -> 47 | H38: =F38-G38 -> 362 | R38: 0 | S38: =H38-R38 -> 362
A39: 26 | B39: Kloramfenikol Salep Mata | C39: Tube | E39: ='PENERIMAAN OBAT PROGRAM'!G34 -> 0 | F39: =D39+E39 -> 0 | G39: =DISTRIBUSI!Z208 -> 0 | H39: =F39-G39 -> 0 | R39: 0 | S39: =H39-R39 -> 0
A40: 27 | E40: ='PENERIMAAN OBAT PROGRAM'!G35 -> 0 | F40: =D40+E40 -> 0 | G40: =DISTRIBUSI!Z209 -> 0 | H40: =F40-G40 -> 0 | R40: 0 | S40: =H40-R40 -> 0
A41: 28 | B41: OBAT PROGRAM MALARIA | S41: =H41-R41 -> 0
...

Sheet PEMAKAIAN UNIT
A1: LAPORAN PENGELUARAN OBAT PUSTU DAN UNIT PELAYANAN LAINNYA
A2: UPT PUSKESMAS SUKAMAJU
A3: TAHUN 2026
D5: acc | E5: acc | G5: acc | I5: acc | J5: acc | K5: acc | L5: acc | P5: Bulan | Q5: ='LPLPO GUDANG'!M9 -> : FEBRUARI
A6: NO | B6: Nama Obat | C6: SATUAN | D6: SAPTA MARGA | E6: SALULEMO | F6: KALUKU | G6: TAMBOKE | H6: MINANGA TALLU | I6: LAMPUAWA | J6: T. INDAH | K6: T.SARI | L6: MULYASARI | M6: KETULUNGAN | N6: WONOSARI | O6: TOLANGI | P6: SUKADAMAI | Q6: PONGKASE | R6: APOTIK | S6: UGD | T6: APOTIK 2 | U6: RI | V6: RB | W6: POLI | X6: LAB | Y6: LAIN-LAIN | Z6: JUMLAH
A8: 1 | B8: 2 | C8: 3 | D8: 4 | E8: 5 | F8: 6 | G8: 7 | H8: 8 | I8: 9 | J8: 10 | K8: 11 | L8: 12 | M8: 13 | N8: 14 | O8: 15 | P8: 16 | Q8: 17 | R8: 18 | S8: 19 | T8: 20 | U8: 21 | V8: 22 | W8: 23 | X8: 24 | Y8: 25 | Z8: 26
A9: 1 | B9: Air untuk injeksi amp 25 ml | C9: Ampul | R9: =APOTIK!G8 -> 0 | S9: =DISTRIBUSI!S10 -> 0 | U9: =DISTRIBUSI!U10 -> 0 | V9: =DISTRIBUSI!V10 -> 0 | W9: =DISTRIBUSI!W10 -> 0 | X9: =DISTRIBUSI!X10 -> 0 | Y9: =DISTRIBUSI!Y10 -> 0 | Z9: =SUM(D9:Y9) -> 0
A10: =A9+1 -> 2 | B10: Alopurinol tab 300 mg | C10: Ktk @ 100 tablet | R10: =APOTIK!G9 -> 0 | S10: =DISTRIBUSI!S11 -> 0 | U10: =DISTRIBUSI!U11 -> 0 | V10: =DISTRIBUSI!V11 -> 0 | W10: =DISTRIBUSI!W11 -> 0 | X10: =DISTRIBUSI!X11 -> 0 | Y10: =DISTRIBUSI!Y11 -> 0 | Z10: =SUM(D10:Y10) -> 0
A11: =A10+1 -> 3 | B11: Ambroxol Sirup | C11: Botol | R11: =APOTIK!G10 -> 0 | S11: =DISTRIBUSI!S12 -> 0 | U11: =DISTRIBUSI!U12 -> 0 | V11: =DISTRIBUSI!V12 -> 0 | W11: =DISTRIBUSI!W12 -> 0 | X11: =DISTRIBUSI!X12 -> 0 | Y11: =DISTRIBUSI!Y12 -> 0 | Z11: =SUM(D11:Y11) -> 0
A12: =A11+1 -> 4 | B12: Amlodipin tab 5 mg | C12: Ktk 50 Tablet | R12: =APOTIK!G11 -> 0 | S12: =DISTRIBUSI!S13 -> 0 | U12: =DISTRIBUSI!U13 -> 0 | V12: =DISTRIBUSI!V13 -> 0 | W12: =DISTRIBUSI!W13 -> 0 | X12: =DISTRIBUSI!X13 -> 0 | Y12: =DISTRIBUSI!Y13 -> 0 | Z12: =SUM(D12:Y12) -> 0
A13: =A12+1 -> 5 | B13: Amlodipin Tablet 10 mg | C13: Tablet | R13: =APOTIK!G12 -> 0 | S13: =DISTRIBUSI!S14 -> 0 | U13: =DISTRIBUSI!U14 -> 0 | V13: =DISTRIBUSI!V14 -> 0 | W13: =DISTRIBUSI!W14 -> 0 | X13: =DISTRIBUSI!X14 -> 0 | Y13: =DISTRIBUSI!Y14 -> 0 | Z13: =SUM(D13:Y13) -> 0
A14: =A13+1 -> 6 | B14: Amoksisilin sirup kering 125 mg/5 ml | C14: Botol | R14: =APOTIK!G13 -> 0 | S14: =DISTRIBUSI!S15 -> 0 | U14: =DISTRIBUSI!U15 -> 0 | V14: =DISTRIBUSI!V15 -> 0 | W14: =DISTRIBUSI!W15 -> 0 | X14: =DISTRIBUSI!X15 -> 0 | Y14: =DISTRIBUSI!Y15 -> 0 | Z14: =SUM(D14:Y14) -> 0
A15: =A14+1 -> 7 | B15: Amoksisilin tab 500 mg | C15: Ktk @100 kaplet | R15: =APOTIK!G14 -> 0 | S15: =DISTRIBUSI!S16 -> 0 | U15: =DISTRIBUSI!U16 -> 0 | V15: =DISTRIBUSI!V16 -> 0 | W15: =DISTRIBUSI!W16 -> 0 | X15: =DISTRIBUSI!X16 -> 0 | Y15: =DISTRIBUSI!Y16 -> 0 | Z15: =SUM(D15:Y15) -> 0
A16: =A15+1 -> 8 | B16: Anestetik lokal gigi kombinasi : lidokain hcl 2% + epinefrin 1 : 80.000 inj 2 ml | C16: Ampul | R16: =APOTIK!G15 -> 0 | S16: =DISTRIBUSI!S17 -> 0 | U16: =DISTRIBUSI!U17 -> 0 | V16: =DISTRIBUSI!V17 -> 15 | W16: =DISTRIBUSI!W17 -> 50 | X16: =DISTRIBUSI!X17 -> 0 | Y16: =DISTRIBUSI!Y17 -> 0 | Z16: =SUM(D16:Y16) -> 65
A17: =A16+1 -> 9 | B17: Antasida, kombinasi : aluminium hidroksida 200 mg + magnesium hidroksida 200 mg | C17: Btl 60 ml | R17: =APOTIK!G16 -> 0 | S17: =DISTRIBUSI!S18 -> 0 | U17: =DISTRIBUSI!U18 -> 0 | V17: =DISTRIBUSI!V18 -> 0 | W17: =DISTRIBUSI!W18 -> 0 | X17: =DISTRIBUSI!X18 -> 0 | Y17: =DISTRIBUSI!Y18 -> 0 | Z17: =SUM(D17:Y17) -> 0
A18: =A17+1 -> 10 | B18: Antasida, kombinasi : aluminium hidroksida 200 mg + magnesium hidroksida 200 mg | C18: Ktk @ 100 tablet | R18: =APOTIK!G17 -> 0 | S18: =DISTRIBUSI!S19 -> 0 | U18: =DISTRIBUSI!U19 -> 0 | V18: =DISTRIBUSI!V19 -> 0 | W18: =DISTRIBUSI!W19 -> 0 | X18: =DISTRIBUSI!X19 -> 0 | Y18: =DISTRIBUSI!Y19 -> 0 | Z18: =SUM(D18:Y18) -> 0
A19: =A18+1 -> 11 | B19: Anti Tetanus Serum ( ATS ) 1500 IU | C19: Ampul | R19: =APOTIK!G18 -> 0 | S19: =DISTRIBUSI!S20 -> 0 | U19: =DISTRIBUSI!U20 -> 0 | V19: =DISTRIBUSI!V20 -> 0 | W19: =DISTRIBUSI!W20 -> 0 | X19: =DISTRIBUSI!X20 -> 0 | Y19: =DISTRIBUSI!Y20 -> 0 | Z19: =SUM(D19:Y19) -> 0
A20: =A19+1 -> 12 | B20: Antihemoroid, kombinasi: bismut subgalat 150 mg + heksaklorofen 2,5 mg + lidokain lidokain 10 mg+ seng oksida 120 mg + sup ad 2 g | C20: Suppositoria | R20: =APOTIK!G19 -> 0 | S20: =DISTRIBUSI!S21 -> 0 | U20: =DISTRIBUSI!U21 -> 0 | V20: =DISTRIBUSI!V21 -> 0 | W20: =DISTRIBUSI!W21 -> 0 | X20: =DISTRIBUSI!X21 -> 0 | Y20: =DISTRIBUSI!Y21 -> 0 | Z20: =SUM(D20:Y20) -> 0
A21: =A20+1 -> 13 | B21: Asam asetilsalisilat tab 80 mg (Miniaspi) | C21: Ktk @ 100 tablet | R21: =APOTIK!G20 -> 0 | S21: =DISTRIBUSI!S22 -> 0 | U21: =DISTRIBUSI!U22 -> 0 | V21: =DISTRIBUSI!V22 -> 0 | W21: =DISTRIBUSI!W22 -> 0 | X21: =DISTRIBUSI!X22 -> 0 | Y21: =DISTRIBUSI!Y22 -> 0 | Z21: =SUM(D21:Y21) -> 0
... A28: =A27+1 -> 20 | B28: Atapulgit ( New Antides ) tab 600 mg | C28: Ktk 150 Tablet | R28: =APOTIK!G27 -> 0 | S28: =DISTRIBUSI!S29 -> 0 | U28: =DISTRIBUSI!U29 -> 0 | V28: =DISTRIBUSI!V29 -> 0 | W28: =DISTRIBUSI!W29 -> 0 | X28: =DISTRIBUSI!X29 -> 0 | Y28: =DISTRIBUSI!Y29 -> 0 | Z28: =SUM(D28:Y28) -> 0
A29: =A28+1 -> 21 | B29: Atorvastatin tab 20 mg | R29: =APOTIK!G28 -> 0 | S29: =DISTRIBUSI!S30 -> 0 | U29: =DISTRIBUSI!U30 -> 0 | V29: =DISTRIBUSI!V30 -> 0 | W29: =DISTRIBUSI!W30 -> 0 | X29: =DISTRIBUSI!X30 -> 0 | Y29: =DISTRIBUSI!Y30 -> 0 | Z29: =SUM(D29:Y29) -> 0
A30: =A29+1 -> 22 | B30: Atropin inj 0,25 mg/ml (i.m./i.v./s.k) | C30: Ampul | R30: =APOTIK!G29 -> 0 | S30: =DISTRIBUSI!S31 -> 0 | U30: =DISTRIBUSI!U31 -> 0 | V30: =DISTRIBUSI!V31 -> 0 | W30: =DISTRIBUSI!W31 -> 0 | X30: =DISTRIBUSI!X31 -> 0 | Y30: =DISTRIBUSI!Y31 -> 0 | Z30: =SUM(D30:Y30) -> 0
A31: =A30+1 -> 23 | B31: Bedak Salicyl 2 % 60 gr | C31: Pot | R31: =APOTIK!G30 -> 0 | S31: =DISTRIBUSI!S32 -> 0 | U31: =DISTRIBUSI!U32 -> 0 | V31: =DISTRIBUSI!V32 -> 0 | W31: =DISTRIBUSI!W32 -> 0 | X31: =DISTRIBUSI!X32 -> 0 | Y31: =DISTRIBUSI!Y32 -> 0 | Z31: =SUM(D31:Y31) -> 0
A32: =A31+1 -> 24 | B32: Betahistin Mesilat tab 6 mg | C32: Ktk 10 x 10 tablet | R32: =APOTIK!G31 -> 0 | S32: =DISTRIBUSI!S33 -> 0 | U32: =DISTRIBUSI!U33 -> 0 | V32: =DISTRIBUSI!V33 -> 0 | W32: =DISTRIBUSI!W33 -> 0 | X32: =DISTRIBUSI!X33 -> 0 | Y32: =DISTRIBUSI!Y33 -> 0 | Z32: =SUM(D32:Y32) -> 0
A33: =A32+1 -> 25 | B33: Betametason krim 0,1% | C33: tube @ 5 gram | R33: =APOTIK!G32 -> 0 | S33: =DISTRIBUSI!S34 -> 5 | U33: =DISTRIBUSI!U34 -> 0 | V33: =DISTRIBUSI!V34 -> 0 | W33: =DISTRIBUSI!W34 -> 0 | X33: =DISTRIBUSI!X34 -> 0 | Y33: =DISTRIBUSI!Y34 -> 0 | Z33: =SUM(D33:Y33) -> 5
A34: =A33+1 -> 26 | B34: Bisakodil sup 10 mg ( Dulcolax ) | C34: Suppositoria | R34: =APOTIK!G33 -> 0 | S34: =DISTRIBUSI!S35 -> 0 | U34: =DISTRIBUSI!U35 -> 0 | V34: =DISTRIBUSI!V35 -> 0 | W34: =DISTRIBUSI!W35 -> 0 | X34: =DISTRIBUSI!X35 -> 0 | Y34: =DISTRIBUSI!Y35 -> 0 | Z34: =SUM(D34:Y34) -> 0
A35: =A34+1 -> 27 | B35: Bisakodil sup 5 mg ( Dulcolax ) | C35: Suppositoria | R35: =APOTIK!G34 -> 0 | S35: =DISTRIBUSI!S36 -> 0 | U35: =DISTRIBUSI!U36 -> 0 | V35: =DISTRIBUSI!V36 -> 0 | W35: =DISTRIBUSI!W36 -> 0 | X35: =DISTRIBUSI!X36 -> 0 | Y35: =DISTRIBUSI!Y36 -> 0 | Z35: =SUM(D35:Y35) -> 0
A36: =A35+1 -> 28 | B36: Colcitin 0.5 gr | C36: Ktk 30 tab | R36: =APOTIK!G35 -> 0 | S36: =DISTRIBUSI!S37 -> 0 | U36: =DISTRIBUSI!U37 -> 0 | V36: =DISTRIBUSI!V37 -> 0 | W36: =DISTRIBUSI!W37 -> 0 | X36: =DISTRIBUSI!X37 -> 0 | Y36: =DISTRIBUSI!Y37 -> 0 | Z36: =SUM(D36:Y36) -> 0
A37: =A36+1 -> 29 | B37: Deksametason tab 0,5 mg | C37: Ktk @ 100 tablet | R37: =APOTIK!G36 -> 0 | S37: =DISTRIBUSI!S38 -> 0 | U37: =DISTRIBUSI!U38 -> 0 | V37: =DISTRIBUSI!V38 -> 0 | W37: =DISTRIBUSI!W38 -> 0 | X37: =DISTRIBUSI!X38 -> 0 | Y37: =DISTRIBUSI!Y38 -> 0 | Z37: =SUM(D37:Y37) -> 0
A38: =A37+1 -> 30 | B38: Deksametason inj 5 mg/ml (i.v./i.m.) | C38: Ampul | R38: =APOTIK!G37 -> 0 | S38: =DISTRIBUSI!S39 -> 0 | U38: =DISTRIBUSI!U39 -> 0 | V38: =DISTRIBUSI!V39 -> 0 | W38: =DISTRIBUSI!W39 -> 0 | X38: =DISTRIBUSI!X39 -> 0 | Y38: =DISTRIBUSI!Y39 -> 0 | Z38: =SUM(D38:Y38) -> 0
A39: =A38+1 -> 31 | B39: Dextrose 40% | C39: Botol | R39: =APOTIK!G38 -> 0 | S39: =DISTRIBUSI!S40 -> 0 | U39: =DISTRIBUSI!U40 -> 0 | V39: =DISTRIBUSI!V40 -> 0 | W39: =DISTRIBUSI!W40 -> 0 | X39: =DISTRIBUSI!X40 -> 0 | Y39: =DISTRIBUSI!Y40 -> 0 | Z39: =SUM(D39:Y39) -> 0
A40: =A39+1 -> 32 | B40: Diazepam inj 10 mg/ 2 ml ( i v./i.m .) stesolid | C40: Ampul @ 2 ml | R40: =APOTIK!G39 -> 0 | S40: =DISTRIBUSI!S41 -> 0 | U40: =DISTRIBUSI!U41 -> 0 | V40: =DISTRIBUSI!V41 -> 0 | W40: =DISTRIBUSI!W41 -> 0 | X40: =DISTRIBUSI!X41 -> 0 | Y40: =DISTRIBUSI!Y41 -> 0 | Z40: =SUM(D40:Y40) -> 0
A41: =A40+1 -> 33 | B41: Diazepam lar rektal 5 mg/2,5 ml ( Stesolid ) | C41: Tube 5 mg/2,5 ml | R41: =APOTIK!G40 -> 0 | S41: =DISTRIBUSI!S42 -> 0 | U41: =DISTRIBUSI!U42 -> 0 | V41: =DISTRIBUSI!V42 -> 0 | W41: =DISTRIBUSI!W42 -> 0 | X41: =DISTRIBUSI!X42 -> 0 | Y41: =DISTRIBUSI!Y42 -> 0 | Z41: =SUM(D41:Y41) -> 0
... A113: =A112+1 -> 105 | B113: Ringer Laktat Larutan | C113: Botol @ 500 ml | R113: =APOTIK!G112 -> 0 | S113: =DISTRIBUSI!S114 -> 20 | U113: =DISTRIBUSI!U114 -> 0 | V113: =DISTRIBUSI!V114 -> 20 | W113: =DISTRIBUSI!W114 -> 0 | X113: =DISTRIBUSI!X114 -> 0 | Y113: =DISTRIBUSI!Y114 -> 0 | Z113: =SUM(D113:Y113) -> 40
A114: =A113+1 -> 106 | B114: Resperidone tab | R114: =APOTIK!G113 -> 0 | S114: =DISTRIBUSI!S115 -> 0 | U114: =DISTRIBUSI!U115 -> 0 | V114: =DISTRIBUSI!V115 -> 0 | W114: =DISTRIBUSI!W115 -> 0 | X114: =DISTRIBUSI!X115 -> 0 | Y114: =DISTRIBUSI!Y115 -> 0 | Z114: =SUM(D114:Y114) -> 0
A115: =A114+1 -> 107 | B115: Salbutamol nebules vial 2,5 mg (Meprovent) | C115: Ampul | R115: =APOTIK!G114 -> 0 | S115: =DISTRIBUSI!S116 -> 10 | U115: =DISTRIBUSI!U116 -> 0 | V115: =DISTRIBUSI!V116 -> 0 | W115: =DISTRIBUSI!W116 -> 0 | X115: =DISTRIBUSI!X116 -> 0 | Y115: =DISTRIBUSI!Y116 -> 0 | Z115: =SUM(D115:Y115) -> 10
A116: =A115+1 -> 108 | B116: Salbutamol tab 4 mg | C116: Ktk @ 100 tablet | R116: =APOTIK!G115 -> 0 | S116: =DISTRIBUSI!S117 -> 0 | U116: =DISTRIBUSI!U117 -> 0 | V116: =DISTRIBUSI!V117 -> 0 | W116: =DISTRIBUSI!W117 -> 0 | X116: =DISTRIBUSI!X117 -> 0 | Y116: =DISTRIBUSI!Y117 -> 0 | Z116: =SUM(D116:Y116) -> 0
A117: =A116+1 -> 109 | B117: Salep 2-4, kombinasi : asam salisilat 2 %+ belerang endap 4 % | C117: pot @ 30 gram | R117: =APOTIK!G116 -> 0 | S117: =DISTRIBUSI!S118 -> 0 | U117: =DISTRIBUSI!U118 -> 0 | V117: =DISTRIBUSI!V118 -> 0 | W117: =DISTRIBUSI!W118 -> 0 | X117: =DISTRIBUSI!X118 -> 0 | Y117: =DISTRIBUSI!Y118 -> 0 | Z117: =SUM(D117:Y117) -> 0
A118: =A117+1 -> 110 | B118: Sefadroksil kapsul 500 mg | C118: Ktk @ 100 tablet | R118: =APOTIK!G117 -> 0 | S118: =DISTRIBUSI!S119 -> 0 | U118: =DISTRIBUSI!U119 -> 0 | V118: =DISTRIBUSI!V119 -> 0 | W118: =DISTRIBUSI!W119 -> 0 | X118: =DISTRIBUSI!X119 -> 0 | Y118: =DISTRIBUSI!Y119 -> 0 | Z118: =SUM(D118:Y118) -> 0
A119: =A118+1 -> 111 | B119: Sefotaksim serb inj 1.000 mg/vial | C119: Vial | R119: =APOTIK!G118 -> 0 | S119: =DISTRIBUSI!S120 -> 0 | U119: =DISTRIBUSI!U120 -> 0 | V119: =DISTRIBUSI!V120 -> 0 | W119: =DISTRIBUSI!W120 -> 0 | X119: =DISTRIBUSI!X120 -> 0 | Y119: =DISTRIBUSI!Y120 -> 0 | Z119: =SUM(D119:Y119) -> 0
...

Sheet SISA STOK UNIT
A1: REKAPAN PEMAKAIAN DAN SISA STOK OBAT PUSTU DAN UNIT LAYANAN LAINNYA
A2: UPT PUSKESMAS SUKAMAJU
A3: TAHUN 2025
